2025-04-20 21:20:17,250 INFO    MainThread:11431 [wandb_init.py:setup_run_log_directory():662] Logging user logs to /Users/kovarthanan/Acedamic/City, University of London/INM705 - Image Analysis/AI-Generated-Image-Detector/wandb/run-20250420_212017-u8a3jalo/logs/debug.log
2025-04-20 21:20:17,250 INFO    MainThread:11431 [wandb_init.py:setup_run_log_directory():663] Logging internal logs to /Users/kovarthanan/Acedamic/City, University of London/INM705 - Image Analysis/AI-Generated-Image-Detector/wandb/run-20250420_212017-u8a3jalo/logs/debug-internal.log
2025-04-20 21:20:17,250 INFO    MainThread:11431 [wandb_init.py:init():781] calling init triggers
2025-04-20 21:20:17,250 INFO    MainThread:11431 [wandb_init.py:init():786] wandb.init called with sweep_config: {}
config: {'epochs': 5, 'batch_size': 32, 'lr': 5e-05, '_wandb': {}}
2025-04-20 21:20:17,250 INFO    MainThread:11431 [wandb_init.py:init():798] finishing previous run: pjrbl5uu
2025-04-20 21:20:19,728 INFO    MainThread:11431 [wandb_init.py:init():809] starting backend
2025-04-20 21:20:19,728 INFO    MainThread:11431 [wandb_init.py:init():813] sending inform_init request
2025-04-20 21:20:19,729 INFO    MainThread:11431 [backend.py:_multiprocessing_setup():101] multiprocessing start_methods=spawn,fork,forkserver, using: spawn
2025-04-20 21:20:19,729 INFO    MainThread:11431 [wandb_init.py:init():823] backend started and connected
2025-04-20 21:20:19,737 INFO    MainThread:11431 [wandb_run.py:_label_probe_notebook():1267] probe notebook
2025-04-20 21:20:19,739 INFO    MainThread:11431 [wandb_init.py:init():915] updated telemetry
2025-04-20 21:20:19,769 INFO    MainThread:11431 [wandb_init.py:init():939] communicating run to backend with 90.0 second timeout
2025-04-20 21:20:20,517 INFO    MainThread:11431 [wandb_init.py:init():1014] starting run threads in backend
2025-04-20 21:20:20,599 INFO    MainThread:11431 [wandb_run.py:_console_start():2454] atexit reg
2025-04-20 21:20:20,599 INFO    MainThread:11431 [wandb_run.py:_redirect():2306] redirect: wrap_raw
2025-04-20 21:20:20,600 INFO    MainThread:11431 [wandb_run.py:_redirect():2371] Wrapping output streams.
2025-04-20 21:20:20,600 INFO    MainThread:11431 [wandb_run.py:_redirect():2394] Redirects installed.
2025-04-20 21:20:20,601 INFO    MainThread:11431 [wandb_init.py:init():1056] run started, returning control to user process
2025-04-20 21:20:27,025 INFO    MainThread:11431 [wandb_watch.py:_watch():71] Watching
2025-04-20 21:25:43,085 WARNING MsgRouterThr:11431 [router.py:message_loop():63] [no run ID] message_loop has been closed
Traceback (most recent call last):
  File "/Users/kovarthanan/Acedamic/City, University of London/INM705 - Image Analysis/AI-Generated-Image-Detector/.venv/lib/python3.10/site-packages/wandb/sdk/interface/router_sock.py", line 27, in _read_message
    return self._sock_client.read_server_response(timeout=1)
  File "/Users/kovarthanan/Acedamic/City, University of London/INM705 - Image Analysis/AI-Generated-Image-Detector/.venv/lib/python3.10/site-packages/wandb/sdk/lib/sock_client.py", line 235, in read_server_response
    data = self._read_packet_bytes(timeout=timeout)
  File "/Users/kovarthanan/Acedamic/City, University of London/INM705 - Image Analysis/AI-Generated-Image-Detector/.venv/lib/python3.10/site-packages/wandb/sdk/lib/sock_client.py", line 220, in _read_packet_bytes
    raise SockClientClosedError
wandb.sdk.lib.sock_client.SockClientClosedError

The above exception was the direct cause of the following exception:

Traceback (most recent call last):
  File "/Users/kovarthanan/Acedamic/City, University of London/INM705 - Image Analysis/AI-Generated-Image-Detector/.venv/lib/python3.10/site-packages/wandb/sdk/interface/router.py", line 56, in message_loop
    msg = self._read_message()
  File "/Users/kovarthanan/Acedamic/City, University of London/INM705 - Image Analysis/AI-Generated-Image-Detector/.venv/lib/python3.10/site-packages/wandb/sdk/interface/router_sock.py", line 29, in _read_message
    raise MessageRouterClosedError from e
wandb.sdk.interface.router.MessageRouterClosedError
2025-04-20 21:25:43,091 INFO    MsgRouterThr:11431 [mailbox.py:close():129] [no run ID] Closing mailbox, abandoning 2 handles.
2025-04-20 21:25:43,094 ERROR   MainThread:11431 [redirect.py:_on_write():661] [no run ID] error in stderr callback
Traceback (most recent call last):
  File "/Users/kovarthanan/Acedamic/City, University of London/INM705 - Image Analysis/AI-Generated-Image-Detector/.venv/lib/python3.10/site-packages/tqdm/std.py", line 1182, in __iter__
    yield obj
GeneratorExit

During handling of the above exception, another exception occurred:

Traceback (most recent call last):
  File "/Users/kovarthanan/Acedamic/City, University of London/INM705 - Image Analysis/AI-Generated-Image-Detector/.venv/lib/python3.10/site-packages/wandb/sdk/lib/redirect.py", line 659, in _on_write
    cb(written_data)
  File "/Users/kovarthanan/Acedamic/City, University of London/INM705 - Image Analysis/AI-Generated-Image-Detector/.venv/lib/python3.10/site-packages/wandb/sdk/wandb_run.py", line 2381, in <lambda>
    lambda data: self._console_raw_callback("stderr", data),
  File "/Users/kovarthanan/Acedamic/City, University of London/INM705 - Image Analysis/AI-Generated-Image-Detector/.venv/lib/python3.10/site-packages/wandb/sdk/wandb_run.py", line 387, in wrapper
    return func(self, *args, **kwargs)
  File "/Users/kovarthanan/Acedamic/City, University of London/INM705 - Image Analysis/AI-Generated-Image-Detector/.venv/lib/python3.10/site-packages/wandb/sdk/wandb_run.py", line 435, in wrapper_fn
    return func(self, *args, **kwargs)
  File "/Users/kovarthanan/Acedamic/City, University of London/INM705 - Image Analysis/AI-Generated-Image-Detector/.venv/lib/python3.10/site-packages/wandb/sdk/wandb_run.py", line 1518, in _console_raw_callback
    self._backend.interface.publish_output_raw(name, data)
  File "/Users/kovarthanan/Acedamic/City, University of London/INM705 - Image Analysis/AI-Generated-Image-Detector/.venv/lib/python3.10/site-packages/wandb/sdk/interface/interface.py", line 761, in publish_output_raw
    self._publish_output_raw(o)
  File "/Users/kovarthanan/Acedamic/City, University of London/INM705 - Image Analysis/AI-Generated-Image-Detector/.venv/lib/python3.10/site-packages/wandb/sdk/interface/interface_shared.py", line 38, in _publish_output_raw
    self._publish(rec)
  File "/Users/kovarthanan/Acedamic/City, University of London/INM705 - Image Analysis/AI-Generated-Image-Detector/.venv/lib/python3.10/site-packages/wandb/sdk/interface/interface_sock.py", line 39, in _publish
    self._sock_client.send_record_publish(record)
  File "/Users/kovarthanan/Acedamic/City, University of London/INM705 - Image Analysis/AI-Generated-Image-Detector/.venv/lib/python3.10/site-packages/wandb/sdk/lib/sock_client.py", line 174, in send_record_publish
    self.send_server_request(server_req)
  File "/Users/kovarthanan/Acedamic/City, University of London/INM705 - Image Analysis/AI-Generated-Image-Detector/.venv/lib/python3.10/site-packages/wandb/sdk/lib/sock_client.py", line 154, in send_server_request
    self._send_message(msg)
  File "/Users/kovarthanan/Acedamic/City, University of London/INM705 - Image Analysis/AI-Generated-Image-Detector/.venv/lib/python3.10/site-packages/wandb/sdk/lib/sock_client.py", line 151, in _send_message
    self._sendall_with_error_handle(header + data)
  File "/Users/kovarthanan/Acedamic/City, University of London/INM705 - Image Analysis/AI-Generated-Image-Detector/.venv/lib/python3.10/site-packages/wandb/sdk/lib/sock_client.py", line 130, in _sendall_with_error_handle
    sent = self._sock.send(data)
BrokenPipeError: [Errno 32] Broken pipe
2025-04-20 21:25:43,098 ERROR   MainThread:11431 [redirect.py:_on_write():661] [no run ID] error in stderr callback
Traceback (most recent call last):
  File "/Users/kovarthanan/Acedamic/City, University of London/INM705 - Image Analysis/AI-Generated-Image-Detector/.venv/lib/python3.10/site-packages/tqdm/std.py", line 1182, in __iter__
    yield obj
GeneratorExit

During handling of the above exception, another exception occurred:

Traceback (most recent call last):
  File "/Users/kovarthanan/Acedamic/City, University of London/INM705 - Image Analysis/AI-Generated-Image-Detector/.venv/lib/python3.10/site-packages/wandb/sdk/lib/redirect.py", line 659, in _on_write
    cb(written_data)
  File "/Users/kovarthanan/Acedamic/City, University of London/INM705 - Image Analysis/AI-Generated-Image-Detector/.venv/lib/python3.10/site-packages/wandb/sdk/wandb_run.py", line 2381, in <lambda>
    lambda data: self._console_raw_callback("stderr", data),
  File "/Users/kovarthanan/Acedamic/City, University of London/INM705 - Image Analysis/AI-Generated-Image-Detector/.venv/lib/python3.10/site-packages/wandb/sdk/wandb_run.py", line 387, in wrapper
    return func(self, *args, **kwargs)
  File "/Users/kovarthanan/Acedamic/City, University of London/INM705 - Image Analysis/AI-Generated-Image-Detector/.venv/lib/python3.10/site-packages/wandb/sdk/wandb_run.py", line 435, in wrapper_fn
    return func(self, *args, **kwargs)
  File "/Users/kovarthanan/Acedamic/City, University of London/INM705 - Image Analysis/AI-Generated-Image-Detector/.venv/lib/python3.10/site-packages/wandb/sdk/wandb_run.py", line 1518, in _console_raw_callback
    self._backend.interface.publish_output_raw(name, data)
  File "/Users/kovarthanan/Acedamic/City, University of London/INM705 - Image Analysis/AI-Generated-Image-Detector/.venv/lib/python3.10/site-packages/wandb/sdk/interface/interface.py", line 761, in publish_output_raw
    self._publish_output_raw(o)
  File "/Users/kovarthanan/Acedamic/City, University of London/INM705 - Image Analysis/AI-Generated-Image-Detector/.venv/lib/python3.10/site-packages/wandb/sdk/interface/interface_shared.py", line 38, in _publish_output_raw
    self._publish(rec)
  File "/Users/kovarthanan/Acedamic/City, University of London/INM705 - Image Analysis/AI-Generated-Image-Detector/.venv/lib/python3.10/site-packages/wandb/sdk/interface/interface_sock.py", line 39, in _publish
    self._sock_client.send_record_publish(record)
  File "/Users/kovarthanan/Acedamic/City, University of London/INM705 - Image Analysis/AI-Generated-Image-Detector/.venv/lib/python3.10/site-packages/wandb/sdk/lib/sock_client.py", line 174, in send_record_publish
    self.send_server_request(server_req)
  File "/Users/kovarthanan/Acedamic/City, University of London/INM705 - Image Analysis/AI-Generated-Image-Detector/.venv/lib/python3.10/site-packages/wandb/sdk/lib/sock_client.py", line 154, in send_server_request
    self._send_message(msg)
  File "/Users/kovarthanan/Acedamic/City, University of London/INM705 - Image Analysis/AI-Generated-Image-Detector/.venv/lib/python3.10/site-packages/wandb/sdk/lib/sock_client.py", line 151, in _send_message
    self._sendall_with_error_handle(header + data)
  File "/Users/kovarthanan/Acedamic/City, University of London/INM705 - Image Analysis/AI-Generated-Image-Detector/.venv/lib/python3.10/site-packages/wandb/sdk/lib/sock_client.py", line 130, in _sendall_with_error_handle
    sent = self._sock.send(data)
BrokenPipeError: [Errno 32] Broken pipe
2025-04-20 21:26:18,810 ERROR   MainThread:11431 [redirect.py:_on_write():661] [no run ID] error in stderr callback
Traceback (most recent call last):
  File "/Users/kovarthanan/Acedamic/City, University of London/INM705 - Image Analysis/AI-Generated-Image-Detector/.venv/lib/python3.10/site-packages/wandb/sdk/lib/redirect.py", line 659, in _on_write
    cb(written_data)
  File "/Users/kovarthanan/Acedamic/City, University of London/INM705 - Image Analysis/AI-Generated-Image-Detector/.venv/lib/python3.10/site-packages/wandb/sdk/wandb_run.py", line 2381, in <lambda>
    lambda data: self._console_raw_callback("stderr", data),
  File "/Users/kovarthanan/Acedamic/City, University of London/INM705 - Image Analysis/AI-Generated-Image-Detector/.venv/lib/python3.10/site-packages/wandb/sdk/wandb_run.py", line 387, in wrapper
    return func(self, *args, **kwargs)
  File "/Users/kovarthanan/Acedamic/City, University of London/INM705 - Image Analysis/AI-Generated-Image-Detector/.venv/lib/python3.10/site-packages/wandb/sdk/wandb_run.py", line 435, in wrapper_fn
    return func(self, *args, **kwargs)
  File "/Users/kovarthanan/Acedamic/City, University of London/INM705 - Image Analysis/AI-Generated-Image-Detector/.venv/lib/python3.10/site-packages/wandb/sdk/wandb_run.py", line 1518, in _console_raw_callback
    self._backend.interface.publish_output_raw(name, data)
  File "/Users/kovarthanan/Acedamic/City, University of London/INM705 - Image Analysis/AI-Generated-Image-Detector/.venv/lib/python3.10/site-packages/wandb/sdk/interface/interface.py", line 761, in publish_output_raw
    self._publish_output_raw(o)
  File "/Users/kovarthanan/Acedamic/City, University of London/INM705 - Image Analysis/AI-Generated-Image-Detector/.venv/lib/python3.10/site-packages/wandb/sdk/interface/interface_shared.py", line 38, in _publish_output_raw
    self._publish(rec)
  File "/Users/kovarthanan/Acedamic/City, University of London/INM705 - Image Analysis/AI-Generated-Image-Detector/.venv/lib/python3.10/site-packages/wandb/sdk/interface/interface_sock.py", line 39, in _publish
    self._sock_client.send_record_publish(record)
  File "/Users/kovarthanan/Acedamic/City, University of London/INM705 - Image Analysis/AI-Generated-Image-Detector/.venv/lib/python3.10/site-packages/wandb/sdk/lib/sock_client.py", line 174, in send_record_publish
    self.send_server_request(server_req)
  File "/Users/kovarthanan/Acedamic/City, University of London/INM705 - Image Analysis/AI-Generated-Image-Detector/.venv/lib/python3.10/site-packages/wandb/sdk/lib/sock_client.py", line 154, in send_server_request
    self._send_message(msg)
  File "/Users/kovarthanan/Acedamic/City, University of London/INM705 - Image Analysis/AI-Generated-Image-Detector/.venv/lib/python3.10/site-packages/wandb/sdk/lib/sock_client.py", line 151, in _send_message
    self._sendall_with_error_handle(header + data)
  File "/Users/kovarthanan/Acedamic/City, University of London/INM705 - Image Analysis/AI-Generated-Image-Detector/.venv/lib/python3.10/site-packages/wandb/sdk/lib/sock_client.py", line 130, in _sendall_with_error_handle
    sent = self._sock.send(data)
BrokenPipeError: [Errno 32] Broken pipe
2025-04-20 21:26:18,845 ERROR   MainThread:11431 [redirect.py:_on_write():661] [no run ID] error in stderr callback
Traceback (most recent call last):
  File "/Users/kovarthanan/Acedamic/City, University of London/INM705 - Image Analysis/AI-Generated-Image-Detector/.venv/lib/python3.10/site-packages/wandb/sdk/lib/redirect.py", line 659, in _on_write
    cb(written_data)
  File "/Users/kovarthanan/Acedamic/City, University of London/INM705 - Image Analysis/AI-Generated-Image-Detector/.venv/lib/python3.10/site-packages/wandb/sdk/wandb_run.py", line 2381, in <lambda>
    lambda data: self._console_raw_callback("stderr", data),
  File "/Users/kovarthanan/Acedamic/City, University of London/INM705 - Image Analysis/AI-Generated-Image-Detector/.venv/lib/python3.10/site-packages/wandb/sdk/wandb_run.py", line 387, in wrapper
    return func(self, *args, **kwargs)
  File "/Users/kovarthanan/Acedamic/City, University of London/INM705 - Image Analysis/AI-Generated-Image-Detector/.venv/lib/python3.10/site-packages/wandb/sdk/wandb_run.py", line 435, in wrapper_fn
    return func(self, *args, **kwargs)
  File "/Users/kovarthanan/Acedamic/City, University of London/INM705 - Image Analysis/AI-Generated-Image-Detector/.venv/lib/python3.10/site-packages/wandb/sdk/wandb_run.py", line 1518, in _console_raw_callback
    self._backend.interface.publish_output_raw(name, data)
  File "/Users/kovarthanan/Acedamic/City, University of London/INM705 - Image Analysis/AI-Generated-Image-Detector/.venv/lib/python3.10/site-packages/wandb/sdk/interface/interface.py", line 761, in publish_output_raw
    self._publish_output_raw(o)
  File "/Users/kovarthanan/Acedamic/City, University of London/INM705 - Image Analysis/AI-Generated-Image-Detector/.venv/lib/python3.10/site-packages/wandb/sdk/interface/interface_shared.py", line 38, in _publish_output_raw
    self._publish(rec)
  File "/Users/kovarthanan/Acedamic/City, University of London/INM705 - Image Analysis/AI-Generated-Image-Detector/.venv/lib/python3.10/site-packages/wandb/sdk/interface/interface_sock.py", line 39, in _publish
    self._sock_client.send_record_publish(record)
  File "/Users/kovarthanan/Acedamic/City, University of London/INM705 - Image Analysis/AI-Generated-Image-Detector/.venv/lib/python3.10/site-packages/wandb/sdk/lib/sock_client.py", line 174, in send_record_publish
    self.send_server_request(server_req)
  File "/Users/kovarthanan/Acedamic/City, University of London/INM705 - Image Analysis/AI-Generated-Image-Detector/.venv/lib/python3.10/site-packages/wandb/sdk/lib/sock_client.py", line 154, in send_server_request
    self._send_message(msg)
  File "/Users/kovarthanan/Acedamic/City, University of London/INM705 - Image Analysis/AI-Generated-Image-Detector/.venv/lib/python3.10/site-packages/wandb/sdk/lib/sock_client.py", line 151, in _send_message
    self._sendall_with_error_handle(header + data)
  File "/Users/kovarthanan/Acedamic/City, University of London/INM705 - Image Analysis/AI-Generated-Image-Detector/.venv/lib/python3.10/site-packages/wandb/sdk/lib/sock_client.py", line 130, in _sendall_with_error_handle
    sent = self._sock.send(data)
BrokenPipeError: [Errno 32] Broken pipe
2025-04-20 21:26:22,095 ERROR   MainThread:11431 [redirect.py:_on_write():661] [no run ID] error in stderr callback
Traceback (most recent call last):
  File "/Users/kovarthanan/Acedamic/City, University of London/INM705 - Image Analysis/AI-Generated-Image-Detector/.venv/lib/python3.10/site-packages/wandb/sdk/lib/redirect.py", line 659, in _on_write
    cb(written_data)
  File "/Users/kovarthanan/Acedamic/City, University of London/INM705 - Image Analysis/AI-Generated-Image-Detector/.venv/lib/python3.10/site-packages/wandb/sdk/wandb_run.py", line 2381, in <lambda>
    lambda data: self._console_raw_callback("stderr", data),
  File "/Users/kovarthanan/Acedamic/City, University of London/INM705 - Image Analysis/AI-Generated-Image-Detector/.venv/lib/python3.10/site-packages/wandb/sdk/wandb_run.py", line 387, in wrapper
    return func(self, *args, **kwargs)
  File "/Users/kovarthanan/Acedamic/City, University of London/INM705 - Image Analysis/AI-Generated-Image-Detector/.venv/lib/python3.10/site-packages/wandb/sdk/wandb_run.py", line 435, in wrapper_fn
    return func(self, *args, **kwargs)
  File "/Users/kovarthanan/Acedamic/City, University of London/INM705 - Image Analysis/AI-Generated-Image-Detector/.venv/lib/python3.10/site-packages/wandb/sdk/wandb_run.py", line 1518, in _console_raw_callback
    self._backend.interface.publish_output_raw(name, data)
  File "/Users/kovarthanan/Acedamic/City, University of London/INM705 - Image Analysis/AI-Generated-Image-Detector/.venv/lib/python3.10/site-packages/wandb/sdk/interface/interface.py", line 761, in publish_output_raw
    self._publish_output_raw(o)
  File "/Users/kovarthanan/Acedamic/City, University of London/INM705 - Image Analysis/AI-Generated-Image-Detector/.venv/lib/python3.10/site-packages/wandb/sdk/interface/interface_shared.py", line 38, in _publish_output_raw
    self._publish(rec)
  File "/Users/kovarthanan/Acedamic/City, University of London/INM705 - Image Analysis/AI-Generated-Image-Detector/.venv/lib/python3.10/site-packages/wandb/sdk/interface/interface_sock.py", line 39, in _publish
    self._sock_client.send_record_publish(record)
  File "/Users/kovarthanan/Acedamic/City, University of London/INM705 - Image Analysis/AI-Generated-Image-Detector/.venv/lib/python3.10/site-packages/wandb/sdk/lib/sock_client.py", line 174, in send_record_publish
    self.send_server_request(server_req)
  File "/Users/kovarthanan/Acedamic/City, University of London/INM705 - Image Analysis/AI-Generated-Image-Detector/.venv/lib/python3.10/site-packages/wandb/sdk/lib/sock_client.py", line 154, in send_server_request
    self._send_message(msg)
  File "/Users/kovarthanan/Acedamic/City, University of London/INM705 - Image Analysis/AI-Generated-Image-Detector/.venv/lib/python3.10/site-packages/wandb/sdk/lib/sock_client.py", line 151, in _send_message
    self._sendall_with_error_handle(header + data)
  File "/Users/kovarthanan/Acedamic/City, University of London/INM705 - Image Analysis/AI-Generated-Image-Detector/.venv/lib/python3.10/site-packages/wandb/sdk/lib/sock_client.py", line 130, in _sendall_with_error_handle
    sent = self._sock.send(data)
BrokenPipeError: [Errno 32] Broken pipe
2025-04-20 21:26:22,207 ERROR   MainThread:11431 [redirect.py:_on_write():661] [no run ID] error in stderr callback
Traceback (most recent call last):
  File "/Users/kovarthanan/Acedamic/City, University of London/INM705 - Image Analysis/AI-Generated-Image-Detector/.venv/lib/python3.10/site-packages/wandb/sdk/lib/redirect.py", line 659, in _on_write
    cb(written_data)
  File "/Users/kovarthanan/Acedamic/City, University of London/INM705 - Image Analysis/AI-Generated-Image-Detector/.venv/lib/python3.10/site-packages/wandb/sdk/wandb_run.py", line 2381, in <lambda>
    lambda data: self._console_raw_callback("stderr", data),
  File "/Users/kovarthanan/Acedamic/City, University of London/INM705 - Image Analysis/AI-Generated-Image-Detector/.venv/lib/python3.10/site-packages/wandb/sdk/wandb_run.py", line 387, in wrapper
    return func(self, *args, **kwargs)
  File "/Users/kovarthanan/Acedamic/City, University of London/INM705 - Image Analysis/AI-Generated-Image-Detector/.venv/lib/python3.10/site-packages/wandb/sdk/wandb_run.py", line 435, in wrapper_fn
    return func(self, *args, **kwargs)
  File "/Users/kovarthanan/Acedamic/City, University of London/INM705 - Image Analysis/AI-Generated-Image-Detector/.venv/lib/python3.10/site-packages/wandb/sdk/wandb_run.py", line 1518, in _console_raw_callback
    self._backend.interface.publish_output_raw(name, data)
  File "/Users/kovarthanan/Acedamic/City, University of London/INM705 - Image Analysis/AI-Generated-Image-Detector/.venv/lib/python3.10/site-packages/wandb/sdk/interface/interface.py", line 761, in publish_output_raw
    self._publish_output_raw(o)
  File "/Users/kovarthanan/Acedamic/City, University of London/INM705 - Image Analysis/AI-Generated-Image-Detector/.venv/lib/python3.10/site-packages/wandb/sdk/interface/interface_shared.py", line 38, in _publish_output_raw
    self._publish(rec)
  File "/Users/kovarthanan/Acedamic/City, University of London/INM705 - Image Analysis/AI-Generated-Image-Detector/.venv/lib/python3.10/site-packages/wandb/sdk/interface/interface_sock.py", line 39, in _publish
    self._sock_client.send_record_publish(record)
  File "/Users/kovarthanan/Acedamic/City, University of London/INM705 - Image Analysis/AI-Generated-Image-Detector/.venv/lib/python3.10/site-packages/wandb/sdk/lib/sock_client.py", line 174, in send_record_publish
    self.send_server_request(server_req)
  File "/Users/kovarthanan/Acedamic/City, University of London/INM705 - Image Analysis/AI-Generated-Image-Detector/.venv/lib/python3.10/site-packages/wandb/sdk/lib/sock_client.py", line 154, in send_server_request
    self._send_message(msg)
  File "/Users/kovarthanan/Acedamic/City, University of London/INM705 - Image Analysis/AI-Generated-Image-Detector/.venv/lib/python3.10/site-packages/wandb/sdk/lib/sock_client.py", line 151, in _send_message
    self._sendall_with_error_handle(header + data)
  File "/Users/kovarthanan/Acedamic/City, University of London/INM705 - Image Analysis/AI-Generated-Image-Detector/.venv/lib/python3.10/site-packages/wandb/sdk/lib/sock_client.py", line 130, in _sendall_with_error_handle
    sent = self._sock.send(data)
BrokenPipeError: [Errno 32] Broken pipe
2025-04-20 21:26:22,308 ERROR   MainThread:11431 [redirect.py:_on_write():661] [no run ID] error in stderr callback
Traceback (most recent call last):
  File "/Users/kovarthanan/Acedamic/City, University of London/INM705 - Image Analysis/AI-Generated-Image-Detector/.venv/lib/python3.10/site-packages/wandb/sdk/lib/redirect.py", line 659, in _on_write
    cb(written_data)
  File "/Users/kovarthanan/Acedamic/City, University of London/INM705 - Image Analysis/AI-Generated-Image-Detector/.venv/lib/python3.10/site-packages/wandb/sdk/wandb_run.py", line 2381, in <lambda>
    lambda data: self._console_raw_callback("stderr", data),
  File "/Users/kovarthanan/Acedamic/City, University of London/INM705 - Image Analysis/AI-Generated-Image-Detector/.venv/lib/python3.10/site-packages/wandb/sdk/wandb_run.py", line 387, in wrapper
    return func(self, *args, **kwargs)
  File "/Users/kovarthanan/Acedamic/City, University of London/INM705 - Image Analysis/AI-Generated-Image-Detector/.venv/lib/python3.10/site-packages/wandb/sdk/wandb_run.py", line 435, in wrapper_fn
    return func(self, *args, **kwargs)
  File "/Users/kovarthanan/Acedamic/City, University of London/INM705 - Image Analysis/AI-Generated-Image-Detector/.venv/lib/python3.10/site-packages/wandb/sdk/wandb_run.py", line 1518, in _console_raw_callback
    self._backend.interface.publish_output_raw(name, data)
  File "/Users/kovarthanan/Acedamic/City, University of London/INM705 - Image Analysis/AI-Generated-Image-Detector/.venv/lib/python3.10/site-packages/wandb/sdk/interface/interface.py", line 761, in publish_output_raw
    self._publish_output_raw(o)
  File "/Users/kovarthanan/Acedamic/City, University of London/INM705 - Image Analysis/AI-Generated-Image-Detector/.venv/lib/python3.10/site-packages/wandb/sdk/interface/interface_shared.py", line 38, in _publish_output_raw
    self._publish(rec)
  File "/Users/kovarthanan/Acedamic/City, University of London/INM705 - Image Analysis/AI-Generated-Image-Detector/.venv/lib/python3.10/site-packages/wandb/sdk/interface/interface_sock.py", line 39, in _publish
    self._sock_client.send_record_publish(record)
  File "/Users/kovarthanan/Acedamic/City, University of London/INM705 - Image Analysis/AI-Generated-Image-Detector/.venv/lib/python3.10/site-packages/wandb/sdk/lib/sock_client.py", line 174, in send_record_publish
    self.send_server_request(server_req)
  File "/Users/kovarthanan/Acedamic/City, University of London/INM705 - Image Analysis/AI-Generated-Image-Detector/.venv/lib/python3.10/site-packages/wandb/sdk/lib/sock_client.py", line 154, in send_server_request
    self._send_message(msg)
  File "/Users/kovarthanan/Acedamic/City, University of London/INM705 - Image Analysis/AI-Generated-Image-Detector/.venv/lib/python3.10/site-packages/wandb/sdk/lib/sock_client.py", line 151, in _send_message
    self._sendall_with_error_handle(header + data)
  File "/Users/kovarthanan/Acedamic/City, University of London/INM705 - Image Analysis/AI-Generated-Image-Detector/.venv/lib/python3.10/site-packages/wandb/sdk/lib/sock_client.py", line 130, in _sendall_with_error_handle
    sent = self._sock.send(data)
BrokenPipeError: [Errno 32] Broken pipe
2025-04-20 21:26:22,432 ERROR   MainThread:11431 [redirect.py:_on_write():661] [no run ID] error in stderr callback
Traceback (most recent call last):
  File "/Users/kovarthanan/Acedamic/City, University of London/INM705 - Image Analysis/AI-Generated-Image-Detector/.venv/lib/python3.10/site-packages/wandb/sdk/lib/redirect.py", line 659, in _on_write
    cb(written_data)
  File "/Users/kovarthanan/Acedamic/City, University of London/INM705 - Image Analysis/AI-Generated-Image-Detector/.venv/lib/python3.10/site-packages/wandb/sdk/wandb_run.py", line 2381, in <lambda>
    lambda data: self._console_raw_callback("stderr", data),
  File "/Users/kovarthanan/Acedamic/City, University of London/INM705 - Image Analysis/AI-Generated-Image-Detector/.venv/lib/python3.10/site-packages/wandb/sdk/wandb_run.py", line 387, in wrapper
    return func(self, *args, **kwargs)
  File "/Users/kovarthanan/Acedamic/City, University of London/INM705 - Image Analysis/AI-Generated-Image-Detector/.venv/lib/python3.10/site-packages/wandb/sdk/wandb_run.py", line 435, in wrapper_fn
    return func(self, *args, **kwargs)
  File "/Users/kovarthanan/Acedamic/City, University of London/INM705 - Image Analysis/AI-Generated-Image-Detector/.venv/lib/python3.10/site-packages/wandb/sdk/wandb_run.py", line 1518, in _console_raw_callback
    self._backend.interface.publish_output_raw(name, data)
  File "/Users/kovarthanan/Acedamic/City, University of London/INM705 - Image Analysis/AI-Generated-Image-Detector/.venv/lib/python3.10/site-packages/wandb/sdk/interface/interface.py", line 761, in publish_output_raw
    self._publish_output_raw(o)
  File "/Users/kovarthanan/Acedamic/City, University of London/INM705 - Image Analysis/AI-Generated-Image-Detector/.venv/lib/python3.10/site-packages/wandb/sdk/interface/interface_shared.py", line 38, in _publish_output_raw
    self._publish(rec)
  File "/Users/kovarthanan/Acedamic/City, University of London/INM705 - Image Analysis/AI-Generated-Image-Detector/.venv/lib/python3.10/site-packages/wandb/sdk/interface/interface_sock.py", line 39, in _publish
    self._sock_client.send_record_publish(record)
  File "/Users/kovarthanan/Acedamic/City, University of London/INM705 - Image Analysis/AI-Generated-Image-Detector/.venv/lib/python3.10/site-packages/wandb/sdk/lib/sock_client.py", line 174, in send_record_publish
    self.send_server_request(server_req)
  File "/Users/kovarthanan/Acedamic/City, University of London/INM705 - Image Analysis/AI-Generated-Image-Detector/.venv/lib/python3.10/site-packages/wandb/sdk/lib/sock_client.py", line 154, in send_server_request
    self._send_message(msg)
  File "/Users/kovarthanan/Acedamic/City, University of London/INM705 - Image Analysis/AI-Generated-Image-Detector/.venv/lib/python3.10/site-packages/wandb/sdk/lib/sock_client.py", line 151, in _send_message
    self._sendall_with_error_handle(header + data)
  File "/Users/kovarthanan/Acedamic/City, University of London/INM705 - Image Analysis/AI-Generated-Image-Detector/.venv/lib/python3.10/site-packages/wandb/sdk/lib/sock_client.py", line 130, in _sendall_with_error_handle
    sent = self._sock.send(data)
BrokenPipeError: [Errno 32] Broken pipe
2025-04-20 21:26:22,553 ERROR   MainThread:11431 [redirect.py:_on_write():661] [no run ID] error in stderr callback
Traceback (most recent call last):
  File "/Users/kovarthanan/Acedamic/City, University of London/INM705 - Image Analysis/AI-Generated-Image-Detector/.venv/lib/python3.10/site-packages/wandb/sdk/lib/redirect.py", line 659, in _on_write
    cb(written_data)
  File "/Users/kovarthanan/Acedamic/City, University of London/INM705 - Image Analysis/AI-Generated-Image-Detector/.venv/lib/python3.10/site-packages/wandb/sdk/wandb_run.py", line 2381, in <lambda>
    lambda data: self._console_raw_callback("stderr", data),
  File "/Users/kovarthanan/Acedamic/City, University of London/INM705 - Image Analysis/AI-Generated-Image-Detector/.venv/lib/python3.10/site-packages/wandb/sdk/wandb_run.py", line 387, in wrapper
    return func(self, *args, **kwargs)
  File "/Users/kovarthanan/Acedamic/City, University of London/INM705 - Image Analysis/AI-Generated-Image-Detector/.venv/lib/python3.10/site-packages/wandb/sdk/wandb_run.py", line 435, in wrapper_fn
    return func(self, *args, **kwargs)
  File "/Users/kovarthanan/Acedamic/City, University of London/INM705 - Image Analysis/AI-Generated-Image-Detector/.venv/lib/python3.10/site-packages/wandb/sdk/wandb_run.py", line 1518, in _console_raw_callback
    self._backend.interface.publish_output_raw(name, data)
  File "/Users/kovarthanan/Acedamic/City, University of London/INM705 - Image Analysis/AI-Generated-Image-Detector/.venv/lib/python3.10/site-packages/wandb/sdk/interface/interface.py", line 761, in publish_output_raw
    self._publish_output_raw(o)
  File "/Users/kovarthanan/Acedamic/City, University of London/INM705 - Image Analysis/AI-Generated-Image-Detector/.venv/lib/python3.10/site-packages/wandb/sdk/interface/interface_shared.py", line 38, in _publish_output_raw
    self._publish(rec)
  File "/Users/kovarthanan/Acedamic/City, University of London/INM705 - Image Analysis/AI-Generated-Image-Detector/.venv/lib/python3.10/site-packages/wandb/sdk/interface/interface_sock.py", line 39, in _publish
    self._sock_client.send_record_publish(record)
  File "/Users/kovarthanan/Acedamic/City, University of London/INM705 - Image Analysis/AI-Generated-Image-Detector/.venv/lib/python3.10/site-packages/wandb/sdk/lib/sock_client.py", line 174, in send_record_publish
    self.send_server_request(server_req)
  File "/Users/kovarthanan/Acedamic/City, University of London/INM705 - Image Analysis/AI-Generated-Image-Detector/.venv/lib/python3.10/site-packages/wandb/sdk/lib/sock_client.py", line 154, in send_server_request
    self._send_message(msg)
  File "/Users/kovarthanan/Acedamic/City, University of London/INM705 - Image Analysis/AI-Generated-Image-Detector/.venv/lib/python3.10/site-packages/wandb/sdk/lib/sock_client.py", line 151, in _send_message
    self._sendall_with_error_handle(header + data)
  File "/Users/kovarthanan/Acedamic/City, University of London/INM705 - Image Analysis/AI-Generated-Image-Detector/.venv/lib/python3.10/site-packages/wandb/sdk/lib/sock_client.py", line 130, in _sendall_with_error_handle
    sent = self._sock.send(data)
BrokenPipeError: [Errno 32] Broken pipe
2025-04-20 21:26:22,675 ERROR   MainThread:11431 [redirect.py:_on_write():661] [no run ID] error in stderr callback
Traceback (most recent call last):
  File "/Users/kovarthanan/Acedamic/City, University of London/INM705 - Image Analysis/AI-Generated-Image-Detector/.venv/lib/python3.10/site-packages/wandb/sdk/lib/redirect.py", line 659, in _on_write
    cb(written_data)
  File "/Users/kovarthanan/Acedamic/City, University of London/INM705 - Image Analysis/AI-Generated-Image-Detector/.venv/lib/python3.10/site-packages/wandb/sdk/wandb_run.py", line 2381, in <lambda>
    lambda data: self._console_raw_callback("stderr", data),
  File "/Users/kovarthanan/Acedamic/City, University of London/INM705 - Image Analysis/AI-Generated-Image-Detector/.venv/lib/python3.10/site-packages/wandb/sdk/wandb_run.py", line 387, in wrapper
    return func(self, *args, **kwargs)
  File "/Users/kovarthanan/Acedamic/City, University of London/INM705 - Image Analysis/AI-Generated-Image-Detector/.venv/lib/python3.10/site-packages/wandb/sdk/wandb_run.py", line 435, in wrapper_fn
    return func(self, *args, **kwargs)
  File "/Users/kovarthanan/Acedamic/City, University of London/INM705 - Image Analysis/AI-Generated-Image-Detector/.venv/lib/python3.10/site-packages/wandb/sdk/wandb_run.py", line 1518, in _console_raw_callback
    self._backend.interface.publish_output_raw(name, data)
  File "/Users/kovarthanan/Acedamic/City, University of London/INM705 - Image Analysis/AI-Generated-Image-Detector/.venv/lib/python3.10/site-packages/wandb/sdk/interface/interface.py", line 761, in publish_output_raw
    self._publish_output_raw(o)
  File "/Users/kovarthanan/Acedamic/City, University of London/INM705 - Image Analysis/AI-Generated-Image-Detector/.venv/lib/python3.10/site-packages/wandb/sdk/interface/interface_shared.py", line 38, in _publish_output_raw
    self._publish(rec)
  File "/Users/kovarthanan/Acedamic/City, University of London/INM705 - Image Analysis/AI-Generated-Image-Detector/.venv/lib/python3.10/site-packages/wandb/sdk/interface/interface_sock.py", line 39, in _publish
    self._sock_client.send_record_publish(record)
  File "/Users/kovarthanan/Acedamic/City, University of London/INM705 - Image Analysis/AI-Generated-Image-Detector/.venv/lib/python3.10/site-packages/wandb/sdk/lib/sock_client.py", line 174, in send_record_publish
    self.send_server_request(server_req)
  File "/Users/kovarthanan/Acedamic/City, University of London/INM705 - Image Analysis/AI-Generated-Image-Detector/.venv/lib/python3.10/site-packages/wandb/sdk/lib/sock_client.py", line 154, in send_server_request
    self._send_message(msg)
  File "/Users/kovarthanan/Acedamic/City, University of London/INM705 - Image Analysis/AI-Generated-Image-Detector/.venv/lib/python3.10/site-packages/wandb/sdk/lib/sock_client.py", line 151, in _send_message
    self._sendall_with_error_handle(header + data)
  File "/Users/kovarthanan/Acedamic/City, University of London/INM705 - Image Analysis/AI-Generated-Image-Detector/.venv/lib/python3.10/site-packages/wandb/sdk/lib/sock_client.py", line 130, in _sendall_with_error_handle
    sent = self._sock.send(data)
BrokenPipeError: [Errno 32] Broken pipe
2025-04-20 21:26:22,800 ERROR   MainThread:11431 [redirect.py:_on_write():661] [no run ID] error in stderr callback
Traceback (most recent call last):
  File "/Users/kovarthanan/Acedamic/City, University of London/INM705 - Image Analysis/AI-Generated-Image-Detector/.venv/lib/python3.10/site-packages/wandb/sdk/lib/redirect.py", line 659, in _on_write
    cb(written_data)
  File "/Users/kovarthanan/Acedamic/City, University of London/INM705 - Image Analysis/AI-Generated-Image-Detector/.venv/lib/python3.10/site-packages/wandb/sdk/wandb_run.py", line 2381, in <lambda>
    lambda data: self._console_raw_callback("stderr", data),
  File "/Users/kovarthanan/Acedamic/City, University of London/INM705 - Image Analysis/AI-Generated-Image-Detector/.venv/lib/python3.10/site-packages/wandb/sdk/wandb_run.py", line 387, in wrapper
    return func(self, *args, **kwargs)
  File "/Users/kovarthanan/Acedamic/City, University of London/INM705 - Image Analysis/AI-Generated-Image-Detector/.venv/lib/python3.10/site-packages/wandb/sdk/wandb_run.py", line 435, in wrapper_fn
    return func(self, *args, **kwargs)
  File "/Users/kovarthanan/Acedamic/City, University of London/INM705 - Image Analysis/AI-Generated-Image-Detector/.venv/lib/python3.10/site-packages/wandb/sdk/wandb_run.py", line 1518, in _console_raw_callback
    self._backend.interface.publish_output_raw(name, data)
  File "/Users/kovarthanan/Acedamic/City, University of London/INM705 - Image Analysis/AI-Generated-Image-Detector/.venv/lib/python3.10/site-packages/wandb/sdk/interface/interface.py", line 761, in publish_output_raw
    self._publish_output_raw(o)
  File "/Users/kovarthanan/Acedamic/City, University of London/INM705 - Image Analysis/AI-Generated-Image-Detector/.venv/lib/python3.10/site-packages/wandb/sdk/interface/interface_shared.py", line 38, in _publish_output_raw
    self._publish(rec)
  File "/Users/kovarthanan/Acedamic/City, University of London/INM705 - Image Analysis/AI-Generated-Image-Detector/.venv/lib/python3.10/site-packages/wandb/sdk/interface/interface_sock.py", line 39, in _publish
    self._sock_client.send_record_publish(record)
  File "/Users/kovarthanan/Acedamic/City, University of London/INM705 - Image Analysis/AI-Generated-Image-Detector/.venv/lib/python3.10/site-packages/wandb/sdk/lib/sock_client.py", line 174, in send_record_publish
    self.send_server_request(server_req)
  File "/Users/kovarthanan/Acedamic/City, University of London/INM705 - Image Analysis/AI-Generated-Image-Detector/.venv/lib/python3.10/site-packages/wandb/sdk/lib/sock_client.py", line 154, in send_server_request
    self._send_message(msg)
  File "/Users/kovarthanan/Acedamic/City, University of London/INM705 - Image Analysis/AI-Generated-Image-Detector/.venv/lib/python3.10/site-packages/wandb/sdk/lib/sock_client.py", line 151, in _send_message
    self._sendall_with_error_handle(header + data)
  File "/Users/kovarthanan/Acedamic/City, University of London/INM705 - Image Analysis/AI-Generated-Image-Detector/.venv/lib/python3.10/site-packages/wandb/sdk/lib/sock_client.py", line 130, in _sendall_with_error_handle
    sent = self._sock.send(data)
BrokenPipeError: [Errno 32] Broken pipe
2025-04-20 21:26:22,922 ERROR   MainThread:11431 [redirect.py:_on_write():661] [no run ID] error in stderr callback
Traceback (most recent call last):
  File "/Users/kovarthanan/Acedamic/City, University of London/INM705 - Image Analysis/AI-Generated-Image-Detector/.venv/lib/python3.10/site-packages/wandb/sdk/lib/redirect.py", line 659, in _on_write
    cb(written_data)
  File "/Users/kovarthanan/Acedamic/City, University of London/INM705 - Image Analysis/AI-Generated-Image-Detector/.venv/lib/python3.10/site-packages/wandb/sdk/wandb_run.py", line 2381, in <lambda>
    lambda data: self._console_raw_callback("stderr", data),
  File "/Users/kovarthanan/Acedamic/City, University of London/INM705 - Image Analysis/AI-Generated-Image-Detector/.venv/lib/python3.10/site-packages/wandb/sdk/wandb_run.py", line 387, in wrapper
    return func(self, *args, **kwargs)
  File "/Users/kovarthanan/Acedamic/City, University of London/INM705 - Image Analysis/AI-Generated-Image-Detector/.venv/lib/python3.10/site-packages/wandb/sdk/wandb_run.py", line 435, in wrapper_fn
    return func(self, *args, **kwargs)
  File "/Users/kovarthanan/Acedamic/City, University of London/INM705 - Image Analysis/AI-Generated-Image-Detector/.venv/lib/python3.10/site-packages/wandb/sdk/wandb_run.py", line 1518, in _console_raw_callback
    self._backend.interface.publish_output_raw(name, data)
  File "/Users/kovarthanan/Acedamic/City, University of London/INM705 - Image Analysis/AI-Generated-Image-Detector/.venv/lib/python3.10/site-packages/wandb/sdk/interface/interface.py", line 761, in publish_output_raw
    self._publish_output_raw(o)
  File "/Users/kovarthanan/Acedamic/City, University of London/INM705 - Image Analysis/AI-Generated-Image-Detector/.venv/lib/python3.10/site-packages/wandb/sdk/interface/interface_shared.py", line 38, in _publish_output_raw
    self._publish(rec)
  File "/Users/kovarthanan/Acedamic/City, University of London/INM705 - Image Analysis/AI-Generated-Image-Detector/.venv/lib/python3.10/site-packages/wandb/sdk/interface/interface_sock.py", line 39, in _publish
    self._sock_client.send_record_publish(record)
  File "/Users/kovarthanan/Acedamic/City, University of London/INM705 - Image Analysis/AI-Generated-Image-Detector/.venv/lib/python3.10/site-packages/wandb/sdk/lib/sock_client.py", line 174, in send_record_publish
    self.send_server_request(server_req)
  File "/Users/kovarthanan/Acedamic/City, University of London/INM705 - Image Analysis/AI-Generated-Image-Detector/.venv/lib/python3.10/site-packages/wandb/sdk/lib/sock_client.py", line 154, in send_server_request
    self._send_message(msg)
  File "/Users/kovarthanan/Acedamic/City, University of London/INM705 - Image Analysis/AI-Generated-Image-Detector/.venv/lib/python3.10/site-packages/wandb/sdk/lib/sock_client.py", line 151, in _send_message
    self._sendall_with_error_handle(header + data)
  File "/Users/kovarthanan/Acedamic/City, University of London/INM705 - Image Analysis/AI-Generated-Image-Detector/.venv/lib/python3.10/site-packages/wandb/sdk/lib/sock_client.py", line 130, in _sendall_with_error_handle
    sent = self._sock.send(data)
BrokenPipeError: [Errno 32] Broken pipe
2025-04-20 21:26:23,022 ERROR   MainThread:11431 [redirect.py:_on_write():661] [no run ID] error in stderr callback
Traceback (most recent call last):
  File "/Users/kovarthanan/Acedamic/City, University of London/INM705 - Image Analysis/AI-Generated-Image-Detector/.venv/lib/python3.10/site-packages/wandb/sdk/lib/redirect.py", line 659, in _on_write
    cb(written_data)
  File "/Users/kovarthanan/Acedamic/City, University of London/INM705 - Image Analysis/AI-Generated-Image-Detector/.venv/lib/python3.10/site-packages/wandb/sdk/wandb_run.py", line 2381, in <lambda>
    lambda data: self._console_raw_callback("stderr", data),
  File "/Users/kovarthanan/Acedamic/City, University of London/INM705 - Image Analysis/AI-Generated-Image-Detector/.venv/lib/python3.10/site-packages/wandb/sdk/wandb_run.py", line 387, in wrapper
    return func(self, *args, **kwargs)
  File "/Users/kovarthanan/Acedamic/City, University of London/INM705 - Image Analysis/AI-Generated-Image-Detector/.venv/lib/python3.10/site-packages/wandb/sdk/wandb_run.py", line 435, in wrapper_fn
    return func(self, *args, **kwargs)
  File "/Users/kovarthanan/Acedamic/City, University of London/INM705 - Image Analysis/AI-Generated-Image-Detector/.venv/lib/python3.10/site-packages/wandb/sdk/wandb_run.py", line 1518, in _console_raw_callback
    self._backend.interface.publish_output_raw(name, data)
  File "/Users/kovarthanan/Acedamic/City, University of London/INM705 - Image Analysis/AI-Generated-Image-Detector/.venv/lib/python3.10/site-packages/wandb/sdk/interface/interface.py", line 761, in publish_output_raw
    self._publish_output_raw(o)
  File "/Users/kovarthanan/Acedamic/City, University of London/INM705 - Image Analysis/AI-Generated-Image-Detector/.venv/lib/python3.10/site-packages/wandb/sdk/interface/interface_shared.py", line 38, in _publish_output_raw
    self._publish(rec)
  File "/Users/kovarthanan/Acedamic/City, University of London/INM705 - Image Analysis/AI-Generated-Image-Detector/.venv/lib/python3.10/site-packages/wandb/sdk/interface/interface_sock.py", line 39, in _publish
    self._sock_client.send_record_publish(record)
  File "/Users/kovarthanan/Acedamic/City, University of London/INM705 - Image Analysis/AI-Generated-Image-Detector/.venv/lib/python3.10/site-packages/wandb/sdk/lib/sock_client.py", line 174, in send_record_publish
    self.send_server_request(server_req)
  File "/Users/kovarthanan/Acedamic/City, University of London/INM705 - Image Analysis/AI-Generated-Image-Detector/.venv/lib/python3.10/site-packages/wandb/sdk/lib/sock_client.py", line 154, in send_server_request
    self._send_message(msg)
  File "/Users/kovarthanan/Acedamic/City, University of London/INM705 - Image Analysis/AI-Generated-Image-Detector/.venv/lib/python3.10/site-packages/wandb/sdk/lib/sock_client.py", line 151, in _send_message
    self._sendall_with_error_handle(header + data)
  File "/Users/kovarthanan/Acedamic/City, University of London/INM705 - Image Analysis/AI-Generated-Image-Detector/.venv/lib/python3.10/site-packages/wandb/sdk/lib/sock_client.py", line 130, in _sendall_with_error_handle
    sent = self._sock.send(data)
BrokenPipeError: [Errno 32] Broken pipe
2025-04-20 21:26:23,122 ERROR   MainThread:11431 [redirect.py:_on_write():661] [no run ID] error in stderr callback
Traceback (most recent call last):
  File "/Users/kovarthanan/Acedamic/City, University of London/INM705 - Image Analysis/AI-Generated-Image-Detector/.venv/lib/python3.10/site-packages/wandb/sdk/lib/redirect.py", line 659, in _on_write
    cb(written_data)
  File "/Users/kovarthanan/Acedamic/City, University of London/INM705 - Image Analysis/AI-Generated-Image-Detector/.venv/lib/python3.10/site-packages/wandb/sdk/wandb_run.py", line 2381, in <lambda>
    lambda data: self._console_raw_callback("stderr", data),
  File "/Users/kovarthanan/Acedamic/City, University of London/INM705 - Image Analysis/AI-Generated-Image-Detector/.venv/lib/python3.10/site-packages/wandb/sdk/wandb_run.py", line 387, in wrapper
    return func(self, *args, **kwargs)
  File "/Users/kovarthanan/Acedamic/City, University of London/INM705 - Image Analysis/AI-Generated-Image-Detector/.venv/lib/python3.10/site-packages/wandb/sdk/wandb_run.py", line 435, in wrapper_fn
    return func(self, *args, **kwargs)
  File "/Users/kovarthanan/Acedamic/City, University of London/INM705 - Image Analysis/AI-Generated-Image-Detector/.venv/lib/python3.10/site-packages/wandb/sdk/wandb_run.py", line 1518, in _console_raw_callback
    self._backend.interface.publish_output_raw(name, data)
  File "/Users/kovarthanan/Acedamic/City, University of London/INM705 - Image Analysis/AI-Generated-Image-Detector/.venv/lib/python3.10/site-packages/wandb/sdk/interface/interface.py", line 761, in publish_output_raw
    self._publish_output_raw(o)
  File "/Users/kovarthanan/Acedamic/City, University of London/INM705 - Image Analysis/AI-Generated-Image-Detector/.venv/lib/python3.10/site-packages/wandb/sdk/interface/interface_shared.py", line 38, in _publish_output_raw
    self._publish(rec)
  File "/Users/kovarthanan/Acedamic/City, University of London/INM705 - Image Analysis/AI-Generated-Image-Detector/.venv/lib/python3.10/site-packages/wandb/sdk/interface/interface_sock.py", line 39, in _publish
    self._sock_client.send_record_publish(record)
  File "/Users/kovarthanan/Acedamic/City, University of London/INM705 - Image Analysis/AI-Generated-Image-Detector/.venv/lib/python3.10/site-packages/wandb/sdk/lib/sock_client.py", line 174, in send_record_publish
    self.send_server_request(server_req)
  File "/Users/kovarthanan/Acedamic/City, University of London/INM705 - Image Analysis/AI-Generated-Image-Detector/.venv/lib/python3.10/site-packages/wandb/sdk/lib/sock_client.py", line 154, in send_server_request
    self._send_message(msg)
  File "/Users/kovarthanan/Acedamic/City, University of London/INM705 - Image Analysis/AI-Generated-Image-Detector/.venv/lib/python3.10/site-packages/wandb/sdk/lib/sock_client.py", line 151, in _send_message
    self._sendall_with_error_handle(header + data)
  File "/Users/kovarthanan/Acedamic/City, University of London/INM705 - Image Analysis/AI-Generated-Image-Detector/.venv/lib/python3.10/site-packages/wandb/sdk/lib/sock_client.py", line 130, in _sendall_with_error_handle
    sent = self._sock.send(data)
BrokenPipeError: [Errno 32] Broken pipe
2025-04-20 21:26:23,224 ERROR   MainThread:11431 [redirect.py:_on_write():661] [no run ID] error in stderr callback
Traceback (most recent call last):
  File "/Users/kovarthanan/Acedamic/City, University of London/INM705 - Image Analysis/AI-Generated-Image-Detector/.venv/lib/python3.10/site-packages/wandb/sdk/lib/redirect.py", line 659, in _on_write
    cb(written_data)
  File "/Users/kovarthanan/Acedamic/City, University of London/INM705 - Image Analysis/AI-Generated-Image-Detector/.venv/lib/python3.10/site-packages/wandb/sdk/wandb_run.py", line 2381, in <lambda>
    lambda data: self._console_raw_callback("stderr", data),
  File "/Users/kovarthanan/Acedamic/City, University of London/INM705 - Image Analysis/AI-Generated-Image-Detector/.venv/lib/python3.10/site-packages/wandb/sdk/wandb_run.py", line 387, in wrapper
    return func(self, *args, **kwargs)
  File "/Users/kovarthanan/Acedamic/City, University of London/INM705 - Image Analysis/AI-Generated-Image-Detector/.venv/lib/python3.10/site-packages/wandb/sdk/wandb_run.py", line 435, in wrapper_fn
    return func(self, *args, **kwargs)
  File "/Users/kovarthanan/Acedamic/City, University of London/INM705 - Image Analysis/AI-Generated-Image-Detector/.venv/lib/python3.10/site-packages/wandb/sdk/wandb_run.py", line 1518, in _console_raw_callback
    self._backend.interface.publish_output_raw(name, data)
  File "/Users/kovarthanan/Acedamic/City, University of London/INM705 - Image Analysis/AI-Generated-Image-Detector/.venv/lib/python3.10/site-packages/wandb/sdk/interface/interface.py", line 761, in publish_output_raw
    self._publish_output_raw(o)
  File "/Users/kovarthanan/Acedamic/City, University of London/INM705 - Image Analysis/AI-Generated-Image-Detector/.venv/lib/python3.10/site-packages/wandb/sdk/interface/interface_shared.py", line 38, in _publish_output_raw
    self._publish(rec)
  File "/Users/kovarthanan/Acedamic/City, University of London/INM705 - Image Analysis/AI-Generated-Image-Detector/.venv/lib/python3.10/site-packages/wandb/sdk/interface/interface_sock.py", line 39, in _publish
    self._sock_client.send_record_publish(record)
  File "/Users/kovarthanan/Acedamic/City, University of London/INM705 - Image Analysis/AI-Generated-Image-Detector/.venv/lib/python3.10/site-packages/wandb/sdk/lib/sock_client.py", line 174, in send_record_publish
    self.send_server_request(server_req)
  File "/Users/kovarthanan/Acedamic/City, University of London/INM705 - Image Analysis/AI-Generated-Image-Detector/.venv/lib/python3.10/site-packages/wandb/sdk/lib/sock_client.py", line 154, in send_server_request
    self._send_message(msg)
  File "/Users/kovarthanan/Acedamic/City, University of London/INM705 - Image Analysis/AI-Generated-Image-Detector/.venv/lib/python3.10/site-packages/wandb/sdk/lib/sock_client.py", line 151, in _send_message
    self._sendall_with_error_handle(header + data)
  File "/Users/kovarthanan/Acedamic/City, University of London/INM705 - Image Analysis/AI-Generated-Image-Detector/.venv/lib/python3.10/site-packages/wandb/sdk/lib/sock_client.py", line 130, in _sendall_with_error_handle
    sent = self._sock.send(data)
BrokenPipeError: [Errno 32] Broken pipe
2025-04-20 21:26:23,344 ERROR   MainThread:11431 [redirect.py:_on_write():661] [no run ID] error in stderr callback
Traceback (most recent call last):
  File "/Users/kovarthanan/Acedamic/City, University of London/INM705 - Image Analysis/AI-Generated-Image-Detector/.venv/lib/python3.10/site-packages/wandb/sdk/lib/redirect.py", line 659, in _on_write
    cb(written_data)
  File "/Users/kovarthanan/Acedamic/City, University of London/INM705 - Image Analysis/AI-Generated-Image-Detector/.venv/lib/python3.10/site-packages/wandb/sdk/wandb_run.py", line 2381, in <lambda>
    lambda data: self._console_raw_callback("stderr", data),
  File "/Users/kovarthanan/Acedamic/City, University of London/INM705 - Image Analysis/AI-Generated-Image-Detector/.venv/lib/python3.10/site-packages/wandb/sdk/wandb_run.py", line 387, in wrapper
    return func(self, *args, **kwargs)
  File "/Users/kovarthanan/Acedamic/City, University of London/INM705 - Image Analysis/AI-Generated-Image-Detector/.venv/lib/python3.10/site-packages/wandb/sdk/wandb_run.py", line 435, in wrapper_fn
    return func(self, *args, **kwargs)
  File "/Users/kovarthanan/Acedamic/City, University of London/INM705 - Image Analysis/AI-Generated-Image-Detector/.venv/lib/python3.10/site-packages/wandb/sdk/wandb_run.py", line 1518, in _console_raw_callback
    self._backend.interface.publish_output_raw(name, data)
  File "/Users/kovarthanan/Acedamic/City, University of London/INM705 - Image Analysis/AI-Generated-Image-Detector/.venv/lib/python3.10/site-packages/wandb/sdk/interface/interface.py", line 761, in publish_output_raw
    self._publish_output_raw(o)
  File "/Users/kovarthanan/Acedamic/City, University of London/INM705 - Image Analysis/AI-Generated-Image-Detector/.venv/lib/python3.10/site-packages/wandb/sdk/interface/interface_shared.py", line 38, in _publish_output_raw
    self._publish(rec)
  File "/Users/kovarthanan/Acedamic/City, University of London/INM705 - Image Analysis/AI-Generated-Image-Detector/.venv/lib/python3.10/site-packages/wandb/sdk/interface/interface_sock.py", line 39, in _publish
    self._sock_client.send_record_publish(record)
  File "/Users/kovarthanan/Acedamic/City, University of London/INM705 - Image Analysis/AI-Generated-Image-Detector/.venv/lib/python3.10/site-packages/wandb/sdk/lib/sock_client.py", line 174, in send_record_publish
    self.send_server_request(server_req)
  File "/Users/kovarthanan/Acedamic/City, University of London/INM705 - Image Analysis/AI-Generated-Image-Detector/.venv/lib/python3.10/site-packages/wandb/sdk/lib/sock_client.py", line 154, in send_server_request
    self._send_message(msg)
  File "/Users/kovarthanan/Acedamic/City, University of London/INM705 - Image Analysis/AI-Generated-Image-Detector/.venv/lib/python3.10/site-packages/wandb/sdk/lib/sock_client.py", line 151, in _send_message
    self._sendall_with_error_handle(header + data)
  File "/Users/kovarthanan/Acedamic/City, University of London/INM705 - Image Analysis/AI-Generated-Image-Detector/.venv/lib/python3.10/site-packages/wandb/sdk/lib/sock_client.py", line 130, in _sendall_with_error_handle
    sent = self._sock.send(data)
BrokenPipeError: [Errno 32] Broken pipe
2025-04-20 21:26:23,472 ERROR   MainThread:11431 [redirect.py:_on_write():661] [no run ID] error in stderr callback
Traceback (most recent call last):
  File "/Users/kovarthanan/Acedamic/City, University of London/INM705 - Image Analysis/AI-Generated-Image-Detector/.venv/lib/python3.10/site-packages/wandb/sdk/lib/redirect.py", line 659, in _on_write
    cb(written_data)
  File "/Users/kovarthanan/Acedamic/City, University of London/INM705 - Image Analysis/AI-Generated-Image-Detector/.venv/lib/python3.10/site-packages/wandb/sdk/wandb_run.py", line 2381, in <lambda>
    lambda data: self._console_raw_callback("stderr", data),
  File "/Users/kovarthanan/Acedamic/City, University of London/INM705 - Image Analysis/AI-Generated-Image-Detector/.venv/lib/python3.10/site-packages/wandb/sdk/wandb_run.py", line 387, in wrapper
    return func(self, *args, **kwargs)
  File "/Users/kovarthanan/Acedamic/City, University of London/INM705 - Image Analysis/AI-Generated-Image-Detector/.venv/lib/python3.10/site-packages/wandb/sdk/wandb_run.py", line 435, in wrapper_fn
    return func(self, *args, **kwargs)
  File "/Users/kovarthanan/Acedamic/City, University of London/INM705 - Image Analysis/AI-Generated-Image-Detector/.venv/lib/python3.10/site-packages/wandb/sdk/wandb_run.py", line 1518, in _console_raw_callback
    self._backend.interface.publish_output_raw(name, data)
  File "/Users/kovarthanan/Acedamic/City, University of London/INM705 - Image Analysis/AI-Generated-Image-Detector/.venv/lib/python3.10/site-packages/wandb/sdk/interface/interface.py", line 761, in publish_output_raw
    self._publish_output_raw(o)
  File "/Users/kovarthanan/Acedamic/City, University of London/INM705 - Image Analysis/AI-Generated-Image-Detector/.venv/lib/python3.10/site-packages/wandb/sdk/interface/interface_shared.py", line 38, in _publish_output_raw
    self._publish(rec)
  File "/Users/kovarthanan/Acedamic/City, University of London/INM705 - Image Analysis/AI-Generated-Image-Detector/.venv/lib/python3.10/site-packages/wandb/sdk/interface/interface_sock.py", line 39, in _publish
    self._sock_client.send_record_publish(record)
  File "/Users/kovarthanan/Acedamic/City, University of London/INM705 - Image Analysis/AI-Generated-Image-Detector/.venv/lib/python3.10/site-packages/wandb/sdk/lib/sock_client.py", line 174, in send_record_publish
    self.send_server_request(server_req)
  File "/Users/kovarthanan/Acedamic/City, University of London/INM705 - Image Analysis/AI-Generated-Image-Detector/.venv/lib/python3.10/site-packages/wandb/sdk/lib/sock_client.py", line 154, in send_server_request
    self._send_message(msg)
  File "/Users/kovarthanan/Acedamic/City, University of London/INM705 - Image Analysis/AI-Generated-Image-Detector/.venv/lib/python3.10/site-packages/wandb/sdk/lib/sock_client.py", line 151, in _send_message
    self._sendall_with_error_handle(header + data)
  File "/Users/kovarthanan/Acedamic/City, University of London/INM705 - Image Analysis/AI-Generated-Image-Detector/.venv/lib/python3.10/site-packages/wandb/sdk/lib/sock_client.py", line 130, in _sendall_with_error_handle
    sent = self._sock.send(data)
BrokenPipeError: [Errno 32] Broken pipe
2025-04-20 21:26:23,593 ERROR   MainThread:11431 [redirect.py:_on_write():661] [no run ID] error in stderr callback
Traceback (most recent call last):
  File "/Users/kovarthanan/Acedamic/City, University of London/INM705 - Image Analysis/AI-Generated-Image-Detector/.venv/lib/python3.10/site-packages/wandb/sdk/lib/redirect.py", line 659, in _on_write
    cb(written_data)
  File "/Users/kovarthanan/Acedamic/City, University of London/INM705 - Image Analysis/AI-Generated-Image-Detector/.venv/lib/python3.10/site-packages/wandb/sdk/wandb_run.py", line 2381, in <lambda>
    lambda data: self._console_raw_callback("stderr", data),
  File "/Users/kovarthanan/Acedamic/City, University of London/INM705 - Image Analysis/AI-Generated-Image-Detector/.venv/lib/python3.10/site-packages/wandb/sdk/wandb_run.py", line 387, in wrapper
    return func(self, *args, **kwargs)
  File "/Users/kovarthanan/Acedamic/City, University of London/INM705 - Image Analysis/AI-Generated-Image-Detector/.venv/lib/python3.10/site-packages/wandb/sdk/wandb_run.py", line 435, in wrapper_fn
    return func(self, *args, **kwargs)
  File "/Users/kovarthanan/Acedamic/City, University of London/INM705 - Image Analysis/AI-Generated-Image-Detector/.venv/lib/python3.10/site-packages/wandb/sdk/wandb_run.py", line 1518, in _console_raw_callback
    self._backend.interface.publish_output_raw(name, data)
  File "/Users/kovarthanan/Acedamic/City, University of London/INM705 - Image Analysis/AI-Generated-Image-Detector/.venv/lib/python3.10/site-packages/wandb/sdk/interface/interface.py", line 761, in publish_output_raw
    self._publish_output_raw(o)
  File "/Users/kovarthanan/Acedamic/City, University of London/INM705 - Image Analysis/AI-Generated-Image-Detector/.venv/lib/python3.10/site-packages/wandb/sdk/interface/interface_shared.py", line 38, in _publish_output_raw
    self._publish(rec)
  File "/Users/kovarthanan/Acedamic/City, University of London/INM705 - Image Analysis/AI-Generated-Image-Detector/.venv/lib/python3.10/site-packages/wandb/sdk/interface/interface_sock.py", line 39, in _publish
    self._sock_client.send_record_publish(record)
  File "/Users/kovarthanan/Acedamic/City, University of London/INM705 - Image Analysis/AI-Generated-Image-Detector/.venv/lib/python3.10/site-packages/wandb/sdk/lib/sock_client.py", line 174, in send_record_publish
    self.send_server_request(server_req)
  File "/Users/kovarthanan/Acedamic/City, University of London/INM705 - Image Analysis/AI-Generated-Image-Detector/.venv/lib/python3.10/site-packages/wandb/sdk/lib/sock_client.py", line 154, in send_server_request
    self._send_message(msg)
  File "/Users/kovarthanan/Acedamic/City, University of London/INM705 - Image Analysis/AI-Generated-Image-Detector/.venv/lib/python3.10/site-packages/wandb/sdk/lib/sock_client.py", line 151, in _send_message
    self._sendall_with_error_handle(header + data)
  File "/Users/kovarthanan/Acedamic/City, University of London/INM705 - Image Analysis/AI-Generated-Image-Detector/.venv/lib/python3.10/site-packages/wandb/sdk/lib/sock_client.py", line 130, in _sendall_with_error_handle
    sent = self._sock.send(data)
BrokenPipeError: [Errno 32] Broken pipe
2025-04-20 21:26:23,714 ERROR   MainThread:11431 [redirect.py:_on_write():661] [no run ID] error in stderr callback
Traceback (most recent call last):
  File "/Users/kovarthanan/Acedamic/City, University of London/INM705 - Image Analysis/AI-Generated-Image-Detector/.venv/lib/python3.10/site-packages/wandb/sdk/lib/redirect.py", line 659, in _on_write
    cb(written_data)
  File "/Users/kovarthanan/Acedamic/City, University of London/INM705 - Image Analysis/AI-Generated-Image-Detector/.venv/lib/python3.10/site-packages/wandb/sdk/wandb_run.py", line 2381, in <lambda>
    lambda data: self._console_raw_callback("stderr", data),
  File "/Users/kovarthanan/Acedamic/City, University of London/INM705 - Image Analysis/AI-Generated-Image-Detector/.venv/lib/python3.10/site-packages/wandb/sdk/wandb_run.py", line 387, in wrapper
    return func(self, *args, **kwargs)
  File "/Users/kovarthanan/Acedamic/City, University of London/INM705 - Image Analysis/AI-Generated-Image-Detector/.venv/lib/python3.10/site-packages/wandb/sdk/wandb_run.py", line 435, in wrapper_fn
    return func(self, *args, **kwargs)
  File "/Users/kovarthanan/Acedamic/City, University of London/INM705 - Image Analysis/AI-Generated-Image-Detector/.venv/lib/python3.10/site-packages/wandb/sdk/wandb_run.py", line 1518, in _console_raw_callback
    self._backend.interface.publish_output_raw(name, data)
  File "/Users/kovarthanan/Acedamic/City, University of London/INM705 - Image Analysis/AI-Generated-Image-Detector/.venv/lib/python3.10/site-packages/wandb/sdk/interface/interface.py", line 761, in publish_output_raw
    self._publish_output_raw(o)
  File "/Users/kovarthanan/Acedamic/City, University of London/INM705 - Image Analysis/AI-Generated-Image-Detector/.venv/lib/python3.10/site-packages/wandb/sdk/interface/interface_shared.py", line 38, in _publish_output_raw
    self._publish(rec)
  File "/Users/kovarthanan/Acedamic/City, University of London/INM705 - Image Analysis/AI-Generated-Image-Detector/.venv/lib/python3.10/site-packages/wandb/sdk/interface/interface_sock.py", line 39, in _publish
    self._sock_client.send_record_publish(record)
  File "/Users/kovarthanan/Acedamic/City, University of London/INM705 - Image Analysis/AI-Generated-Image-Detector/.venv/lib/python3.10/site-packages/wandb/sdk/lib/sock_client.py", line 174, in send_record_publish
    self.send_server_request(server_req)
  File "/Users/kovarthanan/Acedamic/City, University of London/INM705 - Image Analysis/AI-Generated-Image-Detector/.venv/lib/python3.10/site-packages/wandb/sdk/lib/sock_client.py", line 154, in send_server_request
    self._send_message(msg)
  File "/Users/kovarthanan/Acedamic/City, University of London/INM705 - Image Analysis/AI-Generated-Image-Detector/.venv/lib/python3.10/site-packages/wandb/sdk/lib/sock_client.py", line 151, in _send_message
    self._sendall_with_error_handle(header + data)
  File "/Users/kovarthanan/Acedamic/City, University of London/INM705 - Image Analysis/AI-Generated-Image-Detector/.venv/lib/python3.10/site-packages/wandb/sdk/lib/sock_client.py", line 130, in _sendall_with_error_handle
    sent = self._sock.send(data)
BrokenPipeError: [Errno 32] Broken pipe
2025-04-20 21:26:23,840 ERROR   MainThread:11431 [redirect.py:_on_write():661] [no run ID] error in stderr callback
Traceback (most recent call last):
  File "/Users/kovarthanan/Acedamic/City, University of London/INM705 - Image Analysis/AI-Generated-Image-Detector/.venv/lib/python3.10/site-packages/wandb/sdk/lib/redirect.py", line 659, in _on_write
    cb(written_data)
  File "/Users/kovarthanan/Acedamic/City, University of London/INM705 - Image Analysis/AI-Generated-Image-Detector/.venv/lib/python3.10/site-packages/wandb/sdk/wandb_run.py", line 2381, in <lambda>
    lambda data: self._console_raw_callback("stderr", data),
  File "/Users/kovarthanan/Acedamic/City, University of London/INM705 - Image Analysis/AI-Generated-Image-Detector/.venv/lib/python3.10/site-packages/wandb/sdk/wandb_run.py", line 387, in wrapper
    return func(self, *args, **kwargs)
  File "/Users/kovarthanan/Acedamic/City, University of London/INM705 - Image Analysis/AI-Generated-Image-Detector/.venv/lib/python3.10/site-packages/wandb/sdk/wandb_run.py", line 435, in wrapper_fn
    return func(self, *args, **kwargs)
  File "/Users/kovarthanan/Acedamic/City, University of London/INM705 - Image Analysis/AI-Generated-Image-Detector/.venv/lib/python3.10/site-packages/wandb/sdk/wandb_run.py", line 1518, in _console_raw_callback
    self._backend.interface.publish_output_raw(name, data)
  File "/Users/kovarthanan/Acedamic/City, University of London/INM705 - Image Analysis/AI-Generated-Image-Detector/.venv/lib/python3.10/site-packages/wandb/sdk/interface/interface.py", line 761, in publish_output_raw
    self._publish_output_raw(o)
  File "/Users/kovarthanan/Acedamic/City, University of London/INM705 - Image Analysis/AI-Generated-Image-Detector/.venv/lib/python3.10/site-packages/wandb/sdk/interface/interface_shared.py", line 38, in _publish_output_raw
    self._publish(rec)
  File "/Users/kovarthanan/Acedamic/City, University of London/INM705 - Image Analysis/AI-Generated-Image-Detector/.venv/lib/python3.10/site-packages/wandb/sdk/interface/interface_sock.py", line 39, in _publish
    self._sock_client.send_record_publish(record)
  File "/Users/kovarthanan/Acedamic/City, University of London/INM705 - Image Analysis/AI-Generated-Image-Detector/.venv/lib/python3.10/site-packages/wandb/sdk/lib/sock_client.py", line 174, in send_record_publish
    self.send_server_request(server_req)
  File "/Users/kovarthanan/Acedamic/City, University of London/INM705 - Image Analysis/AI-Generated-Image-Detector/.venv/lib/python3.10/site-packages/wandb/sdk/lib/sock_client.py", line 154, in send_server_request
    self._send_message(msg)
  File "/Users/kovarthanan/Acedamic/City, University of London/INM705 - Image Analysis/AI-Generated-Image-Detector/.venv/lib/python3.10/site-packages/wandb/sdk/lib/sock_client.py", line 151, in _send_message
    self._sendall_with_error_handle(header + data)
  File "/Users/kovarthanan/Acedamic/City, University of London/INM705 - Image Analysis/AI-Generated-Image-Detector/.venv/lib/python3.10/site-packages/wandb/sdk/lib/sock_client.py", line 130, in _sendall_with_error_handle
    sent = self._sock.send(data)
BrokenPipeError: [Errno 32] Broken pipe
2025-04-20 21:26:23,963 ERROR   MainThread:11431 [redirect.py:_on_write():661] [no run ID] error in stderr callback
Traceback (most recent call last):
  File "/Users/kovarthanan/Acedamic/City, University of London/INM705 - Image Analysis/AI-Generated-Image-Detector/.venv/lib/python3.10/site-packages/wandb/sdk/lib/redirect.py", line 659, in _on_write
    cb(written_data)
  File "/Users/kovarthanan/Acedamic/City, University of London/INM705 - Image Analysis/AI-Generated-Image-Detector/.venv/lib/python3.10/site-packages/wandb/sdk/wandb_run.py", line 2381, in <lambda>
    lambda data: self._console_raw_callback("stderr", data),
  File "/Users/kovarthanan/Acedamic/City, University of London/INM705 - Image Analysis/AI-Generated-Image-Detector/.venv/lib/python3.10/site-packages/wandb/sdk/wandb_run.py", line 387, in wrapper
    return func(self, *args, **kwargs)
  File "/Users/kovarthanan/Acedamic/City, University of London/INM705 - Image Analysis/AI-Generated-Image-Detector/.venv/lib/python3.10/site-packages/wandb/sdk/wandb_run.py", line 435, in wrapper_fn
    return func(self, *args, **kwargs)
  File "/Users/kovarthanan/Acedamic/City, University of London/INM705 - Image Analysis/AI-Generated-Image-Detector/.venv/lib/python3.10/site-packages/wandb/sdk/wandb_run.py", line 1518, in _console_raw_callback
    self._backend.interface.publish_output_raw(name, data)
  File "/Users/kovarthanan/Acedamic/City, University of London/INM705 - Image Analysis/AI-Generated-Image-Detector/.venv/lib/python3.10/site-packages/wandb/sdk/interface/interface.py", line 761, in publish_output_raw
    self._publish_output_raw(o)
  File "/Users/kovarthanan/Acedamic/City, University of London/INM705 - Image Analysis/AI-Generated-Image-Detector/.venv/lib/python3.10/site-packages/wandb/sdk/interface/interface_shared.py", line 38, in _publish_output_raw
    self._publish(rec)
  File "/Users/kovarthanan/Acedamic/City, University of London/INM705 - Image Analysis/AI-Generated-Image-Detector/.venv/lib/python3.10/site-packages/wandb/sdk/interface/interface_sock.py", line 39, in _publish
    self._sock_client.send_record_publish(record)
  File "/Users/kovarthanan/Acedamic/City, University of London/INM705 - Image Analysis/AI-Generated-Image-Detector/.venv/lib/python3.10/site-packages/wandb/sdk/lib/sock_client.py", line 174, in send_record_publish
    self.send_server_request(server_req)
  File "/Users/kovarthanan/Acedamic/City, University of London/INM705 - Image Analysis/AI-Generated-Image-Detector/.venv/lib/python3.10/site-packages/wandb/sdk/lib/sock_client.py", line 154, in send_server_request
    self._send_message(msg)
  File "/Users/kovarthanan/Acedamic/City, University of London/INM705 - Image Analysis/AI-Generated-Image-Detector/.venv/lib/python3.10/site-packages/wandb/sdk/lib/sock_client.py", line 151, in _send_message
    self._sendall_with_error_handle(header + data)
  File "/Users/kovarthanan/Acedamic/City, University of London/INM705 - Image Analysis/AI-Generated-Image-Detector/.venv/lib/python3.10/site-packages/wandb/sdk/lib/sock_client.py", line 130, in _sendall_with_error_handle
    sent = self._sock.send(data)
BrokenPipeError: [Errno 32] Broken pipe
2025-04-20 21:26:24,087 ERROR   MainThread:11431 [redirect.py:_on_write():661] [no run ID] error in stderr callback
Traceback (most recent call last):
  File "/Users/kovarthanan/Acedamic/City, University of London/INM705 - Image Analysis/AI-Generated-Image-Detector/.venv/lib/python3.10/site-packages/wandb/sdk/lib/redirect.py", line 659, in _on_write
    cb(written_data)
  File "/Users/kovarthanan/Acedamic/City, University of London/INM705 - Image Analysis/AI-Generated-Image-Detector/.venv/lib/python3.10/site-packages/wandb/sdk/wandb_run.py", line 2381, in <lambda>
    lambda data: self._console_raw_callback("stderr", data),
  File "/Users/kovarthanan/Acedamic/City, University of London/INM705 - Image Analysis/AI-Generated-Image-Detector/.venv/lib/python3.10/site-packages/wandb/sdk/wandb_run.py", line 387, in wrapper
    return func(self, *args, **kwargs)
  File "/Users/kovarthanan/Acedamic/City, University of London/INM705 - Image Analysis/AI-Generated-Image-Detector/.venv/lib/python3.10/site-packages/wandb/sdk/wandb_run.py", line 435, in wrapper_fn
    return func(self, *args, **kwargs)
  File "/Users/kovarthanan/Acedamic/City, University of London/INM705 - Image Analysis/AI-Generated-Image-Detector/.venv/lib/python3.10/site-packages/wandb/sdk/wandb_run.py", line 1518, in _console_raw_callback
    self._backend.interface.publish_output_raw(name, data)
  File "/Users/kovarthanan/Acedamic/City, University of London/INM705 - Image Analysis/AI-Generated-Image-Detector/.venv/lib/python3.10/site-packages/wandb/sdk/interface/interface.py", line 761, in publish_output_raw
    self._publish_output_raw(o)
  File "/Users/kovarthanan/Acedamic/City, University of London/INM705 - Image Analysis/AI-Generated-Image-Detector/.venv/lib/python3.10/site-packages/wandb/sdk/interface/interface_shared.py", line 38, in _publish_output_raw
    self._publish(rec)
  File "/Users/kovarthanan/Acedamic/City, University of London/INM705 - Image Analysis/AI-Generated-Image-Detector/.venv/lib/python3.10/site-packages/wandb/sdk/interface/interface_sock.py", line 39, in _publish
    self._sock_client.send_record_publish(record)
  File "/Users/kovarthanan/Acedamic/City, University of London/INM705 - Image Analysis/AI-Generated-Image-Detector/.venv/lib/python3.10/site-packages/wandb/sdk/lib/sock_client.py", line 174, in send_record_publish
    self.send_server_request(server_req)
  File "/Users/kovarthanan/Acedamic/City, University of London/INM705 - Image Analysis/AI-Generated-Image-Detector/.venv/lib/python3.10/site-packages/wandb/sdk/lib/sock_client.py", line 154, in send_server_request
    self._send_message(msg)
  File "/Users/kovarthanan/Acedamic/City, University of London/INM705 - Image Analysis/AI-Generated-Image-Detector/.venv/lib/python3.10/site-packages/wandb/sdk/lib/sock_client.py", line 151, in _send_message
    self._sendall_with_error_handle(header + data)
  File "/Users/kovarthanan/Acedamic/City, University of London/INM705 - Image Analysis/AI-Generated-Image-Detector/.venv/lib/python3.10/site-packages/wandb/sdk/lib/sock_client.py", line 130, in _sendall_with_error_handle
    sent = self._sock.send(data)
BrokenPipeError: [Errno 32] Broken pipe
2025-04-20 21:26:24,207 ERROR   MainThread:11431 [redirect.py:_on_write():661] [no run ID] error in stderr callback
Traceback (most recent call last):
  File "/Users/kovarthanan/Acedamic/City, University of London/INM705 - Image Analysis/AI-Generated-Image-Detector/.venv/lib/python3.10/site-packages/wandb/sdk/lib/redirect.py", line 659, in _on_write
    cb(written_data)
  File "/Users/kovarthanan/Acedamic/City, University of London/INM705 - Image Analysis/AI-Generated-Image-Detector/.venv/lib/python3.10/site-packages/wandb/sdk/wandb_run.py", line 2381, in <lambda>
    lambda data: self._console_raw_callback("stderr", data),
  File "/Users/kovarthanan/Acedamic/City, University of London/INM705 - Image Analysis/AI-Generated-Image-Detector/.venv/lib/python3.10/site-packages/wandb/sdk/wandb_run.py", line 387, in wrapper
    return func(self, *args, **kwargs)
  File "/Users/kovarthanan/Acedamic/City, University of London/INM705 - Image Analysis/AI-Generated-Image-Detector/.venv/lib/python3.10/site-packages/wandb/sdk/wandb_run.py", line 435, in wrapper_fn
    return func(self, *args, **kwargs)
  File "/Users/kovarthanan/Acedamic/City, University of London/INM705 - Image Analysis/AI-Generated-Image-Detector/.venv/lib/python3.10/site-packages/wandb/sdk/wandb_run.py", line 1518, in _console_raw_callback
    self._backend.interface.publish_output_raw(name, data)
  File "/Users/kovarthanan/Acedamic/City, University of London/INM705 - Image Analysis/AI-Generated-Image-Detector/.venv/lib/python3.10/site-packages/wandb/sdk/interface/interface.py", line 761, in publish_output_raw
    self._publish_output_raw(o)
  File "/Users/kovarthanan/Acedamic/City, University of London/INM705 - Image Analysis/AI-Generated-Image-Detector/.venv/lib/python3.10/site-packages/wandb/sdk/interface/interface_shared.py", line 38, in _publish_output_raw
    self._publish(rec)
  File "/Users/kovarthanan/Acedamic/City, University of London/INM705 - Image Analysis/AI-Generated-Image-Detector/.venv/lib/python3.10/site-packages/wandb/sdk/interface/interface_sock.py", line 39, in _publish
    self._sock_client.send_record_publish(record)
  File "/Users/kovarthanan/Acedamic/City, University of London/INM705 - Image Analysis/AI-Generated-Image-Detector/.venv/lib/python3.10/site-packages/wandb/sdk/lib/sock_client.py", line 174, in send_record_publish
    self.send_server_request(server_req)
  File "/Users/kovarthanan/Acedamic/City, University of London/INM705 - Image Analysis/AI-Generated-Image-Detector/.venv/lib/python3.10/site-packages/wandb/sdk/lib/sock_client.py", line 154, in send_server_request
    self._send_message(msg)
  File "/Users/kovarthanan/Acedamic/City, University of London/INM705 - Image Analysis/AI-Generated-Image-Detector/.venv/lib/python3.10/site-packages/wandb/sdk/lib/sock_client.py", line 151, in _send_message
    self._sendall_with_error_handle(header + data)
  File "/Users/kovarthanan/Acedamic/City, University of London/INM705 - Image Analysis/AI-Generated-Image-Detector/.venv/lib/python3.10/site-packages/wandb/sdk/lib/sock_client.py", line 130, in _sendall_with_error_handle
    sent = self._sock.send(data)
BrokenPipeError: [Errno 32] Broken pipe
2025-04-20 21:26:24,331 ERROR   MainThread:11431 [redirect.py:_on_write():661] [no run ID] error in stderr callback
Traceback (most recent call last):
  File "/Users/kovarthanan/Acedamic/City, University of London/INM705 - Image Analysis/AI-Generated-Image-Detector/.venv/lib/python3.10/site-packages/wandb/sdk/lib/redirect.py", line 659, in _on_write
    cb(written_data)
  File "/Users/kovarthanan/Acedamic/City, University of London/INM705 - Image Analysis/AI-Generated-Image-Detector/.venv/lib/python3.10/site-packages/wandb/sdk/wandb_run.py", line 2381, in <lambda>
    lambda data: self._console_raw_callback("stderr", data),
  File "/Users/kovarthanan/Acedamic/City, University of London/INM705 - Image Analysis/AI-Generated-Image-Detector/.venv/lib/python3.10/site-packages/wandb/sdk/wandb_run.py", line 387, in wrapper
    return func(self, *args, **kwargs)
  File "/Users/kovarthanan/Acedamic/City, University of London/INM705 - Image Analysis/AI-Generated-Image-Detector/.venv/lib/python3.10/site-packages/wandb/sdk/wandb_run.py", line 435, in wrapper_fn
    return func(self, *args, **kwargs)
  File "/Users/kovarthanan/Acedamic/City, University of London/INM705 - Image Analysis/AI-Generated-Image-Detector/.venv/lib/python3.10/site-packages/wandb/sdk/wandb_run.py", line 1518, in _console_raw_callback
    self._backend.interface.publish_output_raw(name, data)
  File "/Users/kovarthanan/Acedamic/City, University of London/INM705 - Image Analysis/AI-Generated-Image-Detector/.venv/lib/python3.10/site-packages/wandb/sdk/interface/interface.py", line 761, in publish_output_raw
    self._publish_output_raw(o)
  File "/Users/kovarthanan/Acedamic/City, University of London/INM705 - Image Analysis/AI-Generated-Image-Detector/.venv/lib/python3.10/site-packages/wandb/sdk/interface/interface_shared.py", line 38, in _publish_output_raw
    self._publish(rec)
  File "/Users/kovarthanan/Acedamic/City, University of London/INM705 - Image Analysis/AI-Generated-Image-Detector/.venv/lib/python3.10/site-packages/wandb/sdk/interface/interface_sock.py", line 39, in _publish
    self._sock_client.send_record_publish(record)
  File "/Users/kovarthanan/Acedamic/City, University of London/INM705 - Image Analysis/AI-Generated-Image-Detector/.venv/lib/python3.10/site-packages/wandb/sdk/lib/sock_client.py", line 174, in send_record_publish
    self.send_server_request(server_req)
  File "/Users/kovarthanan/Acedamic/City, University of London/INM705 - Image Analysis/AI-Generated-Image-Detector/.venv/lib/python3.10/site-packages/wandb/sdk/lib/sock_client.py", line 154, in send_server_request
    self._send_message(msg)
  File "/Users/kovarthanan/Acedamic/City, University of London/INM705 - Image Analysis/AI-Generated-Image-Detector/.venv/lib/python3.10/site-packages/wandb/sdk/lib/sock_client.py", line 151, in _send_message
    self._sendall_with_error_handle(header + data)
  File "/Users/kovarthanan/Acedamic/City, University of London/INM705 - Image Analysis/AI-Generated-Image-Detector/.venv/lib/python3.10/site-packages/wandb/sdk/lib/sock_client.py", line 130, in _sendall_with_error_handle
    sent = self._sock.send(data)
BrokenPipeError: [Errno 32] Broken pipe
2025-04-20 21:26:24,452 ERROR   MainThread:11431 [redirect.py:_on_write():661] [no run ID] error in stderr callback
Traceback (most recent call last):
  File "/Users/kovarthanan/Acedamic/City, University of London/INM705 - Image Analysis/AI-Generated-Image-Detector/.venv/lib/python3.10/site-packages/wandb/sdk/lib/redirect.py", line 659, in _on_write
    cb(written_data)
  File "/Users/kovarthanan/Acedamic/City, University of London/INM705 - Image Analysis/AI-Generated-Image-Detector/.venv/lib/python3.10/site-packages/wandb/sdk/wandb_run.py", line 2381, in <lambda>
    lambda data: self._console_raw_callback("stderr", data),
  File "/Users/kovarthanan/Acedamic/City, University of London/INM705 - Image Analysis/AI-Generated-Image-Detector/.venv/lib/python3.10/site-packages/wandb/sdk/wandb_run.py", line 387, in wrapper
    return func(self, *args, **kwargs)
  File "/Users/kovarthanan/Acedamic/City, University of London/INM705 - Image Analysis/AI-Generated-Image-Detector/.venv/lib/python3.10/site-packages/wandb/sdk/wandb_run.py", line 435, in wrapper_fn
    return func(self, *args, **kwargs)
  File "/Users/kovarthanan/Acedamic/City, University of London/INM705 - Image Analysis/AI-Generated-Image-Detector/.venv/lib/python3.10/site-packages/wandb/sdk/wandb_run.py", line 1518, in _console_raw_callback
    self._backend.interface.publish_output_raw(name, data)
  File "/Users/kovarthanan/Acedamic/City, University of London/INM705 - Image Analysis/AI-Generated-Image-Detector/.venv/lib/python3.10/site-packages/wandb/sdk/interface/interface.py", line 761, in publish_output_raw
    self._publish_output_raw(o)
  File "/Users/kovarthanan/Acedamic/City, University of London/INM705 - Image Analysis/AI-Generated-Image-Detector/.venv/lib/python3.10/site-packages/wandb/sdk/interface/interface_shared.py", line 38, in _publish_output_raw
    self._publish(rec)
  File "/Users/kovarthanan/Acedamic/City, University of London/INM705 - Image Analysis/AI-Generated-Image-Detector/.venv/lib/python3.10/site-packages/wandb/sdk/interface/interface_sock.py", line 39, in _publish
    self._sock_client.send_record_publish(record)
  File "/Users/kovarthanan/Acedamic/City, University of London/INM705 - Image Analysis/AI-Generated-Image-Detector/.venv/lib/python3.10/site-packages/wandb/sdk/lib/sock_client.py", line 174, in send_record_publish
    self.send_server_request(server_req)
  File "/Users/kovarthanan/Acedamic/City, University of London/INM705 - Image Analysis/AI-Generated-Image-Detector/.venv/lib/python3.10/site-packages/wandb/sdk/lib/sock_client.py", line 154, in send_server_request
    self._send_message(msg)
  File "/Users/kovarthanan/Acedamic/City, University of London/INM705 - Image Analysis/AI-Generated-Image-Detector/.venv/lib/python3.10/site-packages/wandb/sdk/lib/sock_client.py", line 151, in _send_message
    self._sendall_with_error_handle(header + data)
  File "/Users/kovarthanan/Acedamic/City, University of London/INM705 - Image Analysis/AI-Generated-Image-Detector/.venv/lib/python3.10/site-packages/wandb/sdk/lib/sock_client.py", line 130, in _sendall_with_error_handle
    sent = self._sock.send(data)
BrokenPipeError: [Errno 32] Broken pipe
2025-04-20 21:26:24,515 ERROR   MainThread:11431 [redirect.py:_on_write():661] [no run ID] error in stderr callback
Traceback (most recent call last):
  File "/Users/kovarthanan/Acedamic/City, University of London/INM705 - Image Analysis/AI-Generated-Image-Detector/.venv/lib/python3.10/site-packages/tqdm/std.py", line 1182, in __iter__
    yield obj
GeneratorExit

During handling of the above exception, another exception occurred:

Traceback (most recent call last):
  File "/Users/kovarthanan/Acedamic/City, University of London/INM705 - Image Analysis/AI-Generated-Image-Detector/.venv/lib/python3.10/site-packages/wandb/sdk/lib/redirect.py", line 659, in _on_write
    cb(written_data)
  File "/Users/kovarthanan/Acedamic/City, University of London/INM705 - Image Analysis/AI-Generated-Image-Detector/.venv/lib/python3.10/site-packages/wandb/sdk/wandb_run.py", line 2381, in <lambda>
    lambda data: self._console_raw_callback("stderr", data),
  File "/Users/kovarthanan/Acedamic/City, University of London/INM705 - Image Analysis/AI-Generated-Image-Detector/.venv/lib/python3.10/site-packages/wandb/sdk/wandb_run.py", line 387, in wrapper
    return func(self, *args, **kwargs)
  File "/Users/kovarthanan/Acedamic/City, University of London/INM705 - Image Analysis/AI-Generated-Image-Detector/.venv/lib/python3.10/site-packages/wandb/sdk/wandb_run.py", line 435, in wrapper_fn
    return func(self, *args, **kwargs)
  File "/Users/kovarthanan/Acedamic/City, University of London/INM705 - Image Analysis/AI-Generated-Image-Detector/.venv/lib/python3.10/site-packages/wandb/sdk/wandb_run.py", line 1518, in _console_raw_callback
    self._backend.interface.publish_output_raw(name, data)
  File "/Users/kovarthanan/Acedamic/City, University of London/INM705 - Image Analysis/AI-Generated-Image-Detector/.venv/lib/python3.10/site-packages/wandb/sdk/interface/interface.py", line 761, in publish_output_raw
    self._publish_output_raw(o)
  File "/Users/kovarthanan/Acedamic/City, University of London/INM705 - Image Analysis/AI-Generated-Image-Detector/.venv/lib/python3.10/site-packages/wandb/sdk/interface/interface_shared.py", line 38, in _publish_output_raw
    self._publish(rec)
  File "/Users/kovarthanan/Acedamic/City, University of London/INM705 - Image Analysis/AI-Generated-Image-Detector/.venv/lib/python3.10/site-packages/wandb/sdk/interface/interface_sock.py", line 39, in _publish
    self._sock_client.send_record_publish(record)
  File "/Users/kovarthanan/Acedamic/City, University of London/INM705 - Image Analysis/AI-Generated-Image-Detector/.venv/lib/python3.10/site-packages/wandb/sdk/lib/sock_client.py", line 174, in send_record_publish
    self.send_server_request(server_req)
  File "/Users/kovarthanan/Acedamic/City, University of London/INM705 - Image Analysis/AI-Generated-Image-Detector/.venv/lib/python3.10/site-packages/wandb/sdk/lib/sock_client.py", line 154, in send_server_request
    self._send_message(msg)
  File "/Users/kovarthanan/Acedamic/City, University of London/INM705 - Image Analysis/AI-Generated-Image-Detector/.venv/lib/python3.10/site-packages/wandb/sdk/lib/sock_client.py", line 151, in _send_message
    self._sendall_with_error_handle(header + data)
  File "/Users/kovarthanan/Acedamic/City, University of London/INM705 - Image Analysis/AI-Generated-Image-Detector/.venv/lib/python3.10/site-packages/wandb/sdk/lib/sock_client.py", line 130, in _sendall_with_error_handle
    sent = self._sock.send(data)
BrokenPipeError: [Errno 32] Broken pipe
2025-04-20 21:26:24,515 ERROR   MainThread:11431 [redirect.py:_on_write():661] [no run ID] error in stderr callback
Traceback (most recent call last):
  File "/Users/kovarthanan/Acedamic/City, University of London/INM705 - Image Analysis/AI-Generated-Image-Detector/.venv/lib/python3.10/site-packages/tqdm/std.py", line 1182, in __iter__
    yield obj
GeneratorExit

During handling of the above exception, another exception occurred:

Traceback (most recent call last):
  File "/Users/kovarthanan/Acedamic/City, University of London/INM705 - Image Analysis/AI-Generated-Image-Detector/.venv/lib/python3.10/site-packages/wandb/sdk/lib/redirect.py", line 659, in _on_write
    cb(written_data)
  File "/Users/kovarthanan/Acedamic/City, University of London/INM705 - Image Analysis/AI-Generated-Image-Detector/.venv/lib/python3.10/site-packages/wandb/sdk/wandb_run.py", line 2381, in <lambda>
    lambda data: self._console_raw_callback("stderr", data),
  File "/Users/kovarthanan/Acedamic/City, University of London/INM705 - Image Analysis/AI-Generated-Image-Detector/.venv/lib/python3.10/site-packages/wandb/sdk/wandb_run.py", line 387, in wrapper
    return func(self, *args, **kwargs)
  File "/Users/kovarthanan/Acedamic/City, University of London/INM705 - Image Analysis/AI-Generated-Image-Detector/.venv/lib/python3.10/site-packages/wandb/sdk/wandb_run.py", line 435, in wrapper_fn
    return func(self, *args, **kwargs)
  File "/Users/kovarthanan/Acedamic/City, University of London/INM705 - Image Analysis/AI-Generated-Image-Detector/.venv/lib/python3.10/site-packages/wandb/sdk/wandb_run.py", line 1518, in _console_raw_callback
    self._backend.interface.publish_output_raw(name, data)
  File "/Users/kovarthanan/Acedamic/City, University of London/INM705 - Image Analysis/AI-Generated-Image-Detector/.venv/lib/python3.10/site-packages/wandb/sdk/interface/interface.py", line 761, in publish_output_raw
    self._publish_output_raw(o)
  File "/Users/kovarthanan/Acedamic/City, University of London/INM705 - Image Analysis/AI-Generated-Image-Detector/.venv/lib/python3.10/site-packages/wandb/sdk/interface/interface_shared.py", line 38, in _publish_output_raw
    self._publish(rec)
  File "/Users/kovarthanan/Acedamic/City, University of London/INM705 - Image Analysis/AI-Generated-Image-Detector/.venv/lib/python3.10/site-packages/wandb/sdk/interface/interface_sock.py", line 39, in _publish
    self._sock_client.send_record_publish(record)
  File "/Users/kovarthanan/Acedamic/City, University of London/INM705 - Image Analysis/AI-Generated-Image-Detector/.venv/lib/python3.10/site-packages/wandb/sdk/lib/sock_client.py", line 174, in send_record_publish
    self.send_server_request(server_req)
  File "/Users/kovarthanan/Acedamic/City, University of London/INM705 - Image Analysis/AI-Generated-Image-Detector/.venv/lib/python3.10/site-packages/wandb/sdk/lib/sock_client.py", line 154, in send_server_request
    self._send_message(msg)
  File "/Users/kovarthanan/Acedamic/City, University of London/INM705 - Image Analysis/AI-Generated-Image-Detector/.venv/lib/python3.10/site-packages/wandb/sdk/lib/sock_client.py", line 151, in _send_message
    self._sendall_with_error_handle(header + data)
  File "/Users/kovarthanan/Acedamic/City, University of London/INM705 - Image Analysis/AI-Generated-Image-Detector/.venv/lib/python3.10/site-packages/wandb/sdk/lib/sock_client.py", line 130, in _sendall_with_error_handle
    sent = self._sock.send(data)
BrokenPipeError: [Errno 32] Broken pipe
2025-04-20 21:26:24,516 ERROR   MainThread:11431 [redirect.py:_on_write():661] [no run ID] error in stderr callback
Traceback (most recent call last):
  File "/Users/kovarthanan/Acedamic/City, University of London/INM705 - Image Analysis/AI-Generated-Image-Detector/.venv/lib/python3.10/site-packages/tqdm/std.py", line 1182, in __iter__
    yield obj
GeneratorExit

During handling of the above exception, another exception occurred:

Traceback (most recent call last):
  File "/Users/kovarthanan/Acedamic/City, University of London/INM705 - Image Analysis/AI-Generated-Image-Detector/.venv/lib/python3.10/site-packages/wandb/sdk/lib/redirect.py", line 659, in _on_write
    cb(written_data)
  File "/Users/kovarthanan/Acedamic/City, University of London/INM705 - Image Analysis/AI-Generated-Image-Detector/.venv/lib/python3.10/site-packages/wandb/sdk/wandb_run.py", line 2381, in <lambda>
    lambda data: self._console_raw_callback("stderr", data),
  File "/Users/kovarthanan/Acedamic/City, University of London/INM705 - Image Analysis/AI-Generated-Image-Detector/.venv/lib/python3.10/site-packages/wandb/sdk/wandb_run.py", line 387, in wrapper
    return func(self, *args, **kwargs)
  File "/Users/kovarthanan/Acedamic/City, University of London/INM705 - Image Analysis/AI-Generated-Image-Detector/.venv/lib/python3.10/site-packages/wandb/sdk/wandb_run.py", line 435, in wrapper_fn
    return func(self, *args, **kwargs)
  File "/Users/kovarthanan/Acedamic/City, University of London/INM705 - Image Analysis/AI-Generated-Image-Detector/.venv/lib/python3.10/site-packages/wandb/sdk/wandb_run.py", line 1518, in _console_raw_callback
    self._backend.interface.publish_output_raw(name, data)
  File "/Users/kovarthanan/Acedamic/City, University of London/INM705 - Image Analysis/AI-Generated-Image-Detector/.venv/lib/python3.10/site-packages/wandb/sdk/interface/interface.py", line 761, in publish_output_raw
    self._publish_output_raw(o)
  File "/Users/kovarthanan/Acedamic/City, University of London/INM705 - Image Analysis/AI-Generated-Image-Detector/.venv/lib/python3.10/site-packages/wandb/sdk/interface/interface_shared.py", line 38, in _publish_output_raw
    self._publish(rec)
  File "/Users/kovarthanan/Acedamic/City, University of London/INM705 - Image Analysis/AI-Generated-Image-Detector/.venv/lib/python3.10/site-packages/wandb/sdk/interface/interface_sock.py", line 39, in _publish
    self._sock_client.send_record_publish(record)
  File "/Users/kovarthanan/Acedamic/City, University of London/INM705 - Image Analysis/AI-Generated-Image-Detector/.venv/lib/python3.10/site-packages/wandb/sdk/lib/sock_client.py", line 174, in send_record_publish
    self.send_server_request(server_req)
  File "/Users/kovarthanan/Acedamic/City, University of London/INM705 - Image Analysis/AI-Generated-Image-Detector/.venv/lib/python3.10/site-packages/wandb/sdk/lib/sock_client.py", line 154, in send_server_request
    self._send_message(msg)
  File "/Users/kovarthanan/Acedamic/City, University of London/INM705 - Image Analysis/AI-Generated-Image-Detector/.venv/lib/python3.10/site-packages/wandb/sdk/lib/sock_client.py", line 151, in _send_message
    self._sendall_with_error_handle(header + data)
  File "/Users/kovarthanan/Acedamic/City, University of London/INM705 - Image Analysis/AI-Generated-Image-Detector/.venv/lib/python3.10/site-packages/wandb/sdk/lib/sock_client.py", line 130, in _sendall_with_error_handle
    sent = self._sock.send(data)
BrokenPipeError: [Errno 32] Broken pipe
