2025-04-21 03:29:21,945 INFO    MainThread:18782 [wandb_init.py:setup_run_log_directory():662] Logging user logs to /Users/kovarthanan/Acedamic/City, University of London/INM705 - Image Analysis/AI-Generated-Image-Detector/wandb/run-20250421_032921-bqd1odrx/logs/debug.log
2025-04-21 03:29:21,945 INFO    MainThread:18782 [wandb_init.py:setup_run_log_directory():663] Logging internal logs to /Users/kovarthanan/Acedamic/City, University of London/INM705 - Image Analysis/AI-Generated-Image-Detector/wandb/run-20250421_032921-bqd1odrx/logs/debug-internal.log
2025-04-21 03:29:21,945 INFO    MainThread:18782 [wandb_init.py:init():781] calling init triggers
2025-04-21 03:29:21,945 INFO    MainThread:18782 [wandb_init.py:init():786] wandb.init called with sweep_config: {}
config: {'epochs': 5, 'batch_size': 16, 'lr': 5e-05, '_wandb': {}}
2025-04-21 03:29:21,945 INFO    MainThread:18782 [wandb_init.py:init():798] finishing previous run: 8f6h0t6z
2025-04-21 03:29:24,538 INFO    MainThread:18782 [wandb_init.py:init():809] starting backend
2025-04-21 03:29:24,538 INFO    MainThread:18782 [wandb_init.py:init():813] sending inform_init request
2025-04-21 03:29:24,539 INFO    MainThread:18782 [backend.py:_multiprocessing_setup():101] multiprocessing start_methods=spawn,fork,forkserver, using: spawn
2025-04-21 03:29:24,539 INFO    MainThread:18782 [wandb_init.py:init():823] backend started and connected
2025-04-21 03:29:24,541 INFO    MainThread:18782 [wandb_run.py:_label_probe_notebook():1267] probe notebook
2025-04-21 03:29:24,546 INFO    MainThread:18782 [wandb_init.py:init():915] updated telemetry
2025-04-21 03:29:24,581 INFO    MainThread:18782 [wandb_init.py:init():939] communicating run to backend with 90.0 second timeout
2025-04-21 03:29:25,327 INFO    MainThread:18782 [wandb_init.py:init():1014] starting run threads in backend
2025-04-21 03:29:25,395 INFO    MainThread:18782 [wandb_run.py:_console_start():2454] atexit reg
2025-04-21 03:29:25,395 INFO    MainThread:18782 [wandb_run.py:_redirect():2306] redirect: wrap_raw
2025-04-21 03:29:25,395 INFO    MainThread:18782 [wandb_run.py:_redirect():2371] Wrapping output streams.
2025-04-21 03:29:25,395 INFO    MainThread:18782 [wandb_run.py:_redirect():2394] Redirects installed.
2025-04-21 03:29:25,396 INFO    MainThread:18782 [wandb_init.py:init():1056] run started, returning control to user process
2025-04-21 03:29:26,571 INFO    MainThread:18782 [wandb_watch.py:_watch():71] Watching
2025-04-21 03:47:13,453 WARNING MsgRouterThr:18782 [router.py:message_loop():63] [no run ID] message_loop has been closed
Traceback (most recent call last):
  File "/Users/kovarthanan/Acedamic/City, University of London/INM705 - Image Analysis/AI-Generated-Image-Detector/.venv/lib/python3.10/site-packages/wandb/sdk/interface/router_sock.py", line 27, in _read_message
    return self._sock_client.read_server_response(timeout=1)
  File "/Users/kovarthanan/Acedamic/City, University of London/INM705 - Image Analysis/AI-Generated-Image-Detector/.venv/lib/python3.10/site-packages/wandb/sdk/lib/sock_client.py", line 235, in read_server_response
    data = self._read_packet_bytes(timeout=timeout)
  File "/Users/kovarthanan/Acedamic/City, University of London/INM705 - Image Analysis/AI-Generated-Image-Detector/.venv/lib/python3.10/site-packages/wandb/sdk/lib/sock_client.py", line 220, in _read_packet_bytes
    raise SockClientClosedError
wandb.sdk.lib.sock_client.SockClientClosedError

The above exception was the direct cause of the following exception:

Traceback (most recent call last):
  File "/Users/kovarthanan/Acedamic/City, University of London/INM705 - Image Analysis/AI-Generated-Image-Detector/.venv/lib/python3.10/site-packages/wandb/sdk/interface/router.py", line 56, in message_loop
    msg = self._read_message()
  File "/Users/kovarthanan/Acedamic/City, University of London/INM705 - Image Analysis/AI-Generated-Image-Detector/.venv/lib/python3.10/site-packages/wandb/sdk/interface/router_sock.py", line 29, in _read_message
    raise MessageRouterClosedError from e
wandb.sdk.interface.router.MessageRouterClosedError
2025-04-21 03:47:13,455 ERROR   MainThread:18782 [redirect.py:_on_write():661] [no run ID] error in stderr callback
Traceback (most recent call last):
  File "/Users/kovarthanan/Acedamic/City, University of London/INM705 - Image Analysis/AI-Generated-Image-Detector/.venv/lib/python3.10/site-packages/tqdm/std.py", line 1182, in __iter__
    yield obj
GeneratorExit

During handling of the above exception, another exception occurred:

Traceback (most recent call last):
  File "/Users/kovarthanan/Acedamic/City, University of London/INM705 - Image Analysis/AI-Generated-Image-Detector/.venv/lib/python3.10/site-packages/wandb/sdk/lib/redirect.py", line 659, in _on_write
    cb(written_data)
  File "/Users/kovarthanan/Acedamic/City, University of London/INM705 - Image Analysis/AI-Generated-Image-Detector/.venv/lib/python3.10/site-packages/wandb/sdk/wandb_run.py", line 2381, in <lambda>
    lambda data: self._console_raw_callback("stderr", data),
  File "/Users/kovarthanan/Acedamic/City, University of London/INM705 - Image Analysis/AI-Generated-Image-Detector/.venv/lib/python3.10/site-packages/wandb/sdk/wandb_run.py", line 387, in wrapper
    return func(self, *args, **kwargs)
  File "/Users/kovarthanan/Acedamic/City, University of London/INM705 - Image Analysis/AI-Generated-Image-Detector/.venv/lib/python3.10/site-packages/wandb/sdk/wandb_run.py", line 435, in wrapper_fn
    return func(self, *args, **kwargs)
  File "/Users/kovarthanan/Acedamic/City, University of London/INM705 - Image Analysis/AI-Generated-Image-Detector/.venv/lib/python3.10/site-packages/wandb/sdk/wandb_run.py", line 1518, in _console_raw_callback
    self._backend.interface.publish_output_raw(name, data)
  File "/Users/kovarthanan/Acedamic/City, University of London/INM705 - Image Analysis/AI-Generated-Image-Detector/.venv/lib/python3.10/site-packages/wandb/sdk/interface/interface.py", line 761, in publish_output_raw
    self._publish_output_raw(o)
  File "/Users/kovarthanan/Acedamic/City, University of London/INM705 - Image Analysis/AI-Generated-Image-Detector/.venv/lib/python3.10/site-packages/wandb/sdk/interface/interface_shared.py", line 38, in _publish_output_raw
    self._publish(rec)
  File "/Users/kovarthanan/Acedamic/City, University of London/INM705 - Image Analysis/AI-Generated-Image-Detector/.venv/lib/python3.10/site-packages/wandb/sdk/interface/interface_sock.py", line 39, in _publish
    self._sock_client.send_record_publish(record)
  File "/Users/kovarthanan/Acedamic/City, University of London/INM705 - Image Analysis/AI-Generated-Image-Detector/.venv/lib/python3.10/site-packages/wandb/sdk/lib/sock_client.py", line 174, in send_record_publish
    self.send_server_request(server_req)
  File "/Users/kovarthanan/Acedamic/City, University of London/INM705 - Image Analysis/AI-Generated-Image-Detector/.venv/lib/python3.10/site-packages/wandb/sdk/lib/sock_client.py", line 154, in send_server_request
    self._send_message(msg)
  File "/Users/kovarthanan/Acedamic/City, University of London/INM705 - Image Analysis/AI-Generated-Image-Detector/.venv/lib/python3.10/site-packages/wandb/sdk/lib/sock_client.py", line 151, in _send_message
    self._sendall_with_error_handle(header + data)
  File "/Users/kovarthanan/Acedamic/City, University of London/INM705 - Image Analysis/AI-Generated-Image-Detector/.venv/lib/python3.10/site-packages/wandb/sdk/lib/sock_client.py", line 130, in _sendall_with_error_handle
    sent = self._sock.send(data)
BrokenPipeError: [Errno 32] Broken pipe
2025-04-21 03:47:13,455 INFO    MsgRouterThr:18782 [mailbox.py:close():129] [no run ID] Closing mailbox, abandoning 2 handles.
2025-04-21 03:47:13,459 ERROR   MainThread:18782 [redirect.py:_on_write():661] [no run ID] error in stderr callback
Traceback (most recent call last):
  File "/Users/kovarthanan/Acedamic/City, University of London/INM705 - Image Analysis/AI-Generated-Image-Detector/.venv/lib/python3.10/site-packages/tqdm/std.py", line 1182, in __iter__
    yield obj
GeneratorExit

During handling of the above exception, another exception occurred:

Traceback (most recent call last):
  File "/Users/kovarthanan/Acedamic/City, University of London/INM705 - Image Analysis/AI-Generated-Image-Detector/.venv/lib/python3.10/site-packages/wandb/sdk/lib/redirect.py", line 659, in _on_write
    cb(written_data)
  File "/Users/kovarthanan/Acedamic/City, University of London/INM705 - Image Analysis/AI-Generated-Image-Detector/.venv/lib/python3.10/site-packages/wandb/sdk/wandb_run.py", line 2381, in <lambda>
    lambda data: self._console_raw_callback("stderr", data),
  File "/Users/kovarthanan/Acedamic/City, University of London/INM705 - Image Analysis/AI-Generated-Image-Detector/.venv/lib/python3.10/site-packages/wandb/sdk/wandb_run.py", line 387, in wrapper
    return func(self, *args, **kwargs)
  File "/Users/kovarthanan/Acedamic/City, University of London/INM705 - Image Analysis/AI-Generated-Image-Detector/.venv/lib/python3.10/site-packages/wandb/sdk/wandb_run.py", line 435, in wrapper_fn
    return func(self, *args, **kwargs)
  File "/Users/kovarthanan/Acedamic/City, University of London/INM705 - Image Analysis/AI-Generated-Image-Detector/.venv/lib/python3.10/site-packages/wandb/sdk/wandb_run.py", line 1518, in _console_raw_callback
    self._backend.interface.publish_output_raw(name, data)
  File "/Users/kovarthanan/Acedamic/City, University of London/INM705 - Image Analysis/AI-Generated-Image-Detector/.venv/lib/python3.10/site-packages/wandb/sdk/interface/interface.py", line 761, in publish_output_raw
    self._publish_output_raw(o)
  File "/Users/kovarthanan/Acedamic/City, University of London/INM705 - Image Analysis/AI-Generated-Image-Detector/.venv/lib/python3.10/site-packages/wandb/sdk/interface/interface_shared.py", line 38, in _publish_output_raw
    self._publish(rec)
  File "/Users/kovarthanan/Acedamic/City, University of London/INM705 - Image Analysis/AI-Generated-Image-Detector/.venv/lib/python3.10/site-packages/wandb/sdk/interface/interface_sock.py", line 39, in _publish
    self._sock_client.send_record_publish(record)
  File "/Users/kovarthanan/Acedamic/City, University of London/INM705 - Image Analysis/AI-Generated-Image-Detector/.venv/lib/python3.10/site-packages/wandb/sdk/lib/sock_client.py", line 174, in send_record_publish
    self.send_server_request(server_req)
  File "/Users/kovarthanan/Acedamic/City, University of London/INM705 - Image Analysis/AI-Generated-Image-Detector/.venv/lib/python3.10/site-packages/wandb/sdk/lib/sock_client.py", line 154, in send_server_request
    self._send_message(msg)
  File "/Users/kovarthanan/Acedamic/City, University of London/INM705 - Image Analysis/AI-Generated-Image-Detector/.venv/lib/python3.10/site-packages/wandb/sdk/lib/sock_client.py", line 151, in _send_message
    self._sendall_with_error_handle(header + data)
  File "/Users/kovarthanan/Acedamic/City, University of London/INM705 - Image Analysis/AI-Generated-Image-Detector/.venv/lib/python3.10/site-packages/wandb/sdk/lib/sock_client.py", line 130, in _sendall_with_error_handle
    sent = self._sock.send(data)
BrokenPipeError: [Errno 32] Broken pipe
2025-04-21 04:29:24,150 INFO    MainThread:18782 [wandb_run.py:_finish():2189] finishing run avok/INM705-Image/bqd1odrx
2025-04-21 04:29:24,150 ERROR   MainThread:18782 [wandb_init.py:init():1540] [no run ID] error in wandb.init()
Traceback (most recent call last):
  File "/Users/kovarthanan/Acedamic/City, University of London/INM705 - Image Analysis/AI-Generated-Image-Detector/.venv/lib/python3.10/site-packages/wandb/sdk/wandb_init.py", line 1530, in init
    return wi.init(run_settings, run_config)
  File "/Users/kovarthanan/Acedamic/City, University of London/INM705 - Image Analysis/AI-Generated-Image-Detector/.venv/lib/python3.10/site-packages/wandb/sdk/wandb_init.py", line 799, in init
    wandb.run.finish()
  File "/Users/kovarthanan/Acedamic/City, University of London/INM705 - Image Analysis/AI-Generated-Image-Detector/.venv/lib/python3.10/site-packages/wandb/sdk/wandb_run.py", line 387, in wrapper
    return func(self, *args, **kwargs)
  File "/Users/kovarthanan/Acedamic/City, University of London/INM705 - Image Analysis/AI-Generated-Image-Detector/.venv/lib/python3.10/site-packages/wandb/sdk/wandb_run.py", line 483, in wrapper
    return func(self, *args, **kwargs)
  File "/Users/kovarthanan/Acedamic/City, University of London/INM705 - Image Analysis/AI-Generated-Image-Detector/.venv/lib/python3.10/site-packages/wandb/sdk/wandb_run.py", line 425, in wrapper
    return func(self, *args, **kwargs)
  File "/Users/kovarthanan/Acedamic/City, University of London/INM705 - Image Analysis/AI-Generated-Image-Detector/.venv/lib/python3.10/site-packages/wandb/sdk/wandb_run.py", line 2182, in finish
    return self._finish(exit_code)
  File "/Users/kovarthanan/Acedamic/City, University of London/INM705 - Image Analysis/AI-Generated-Image-Detector/.venv/lib/python3.10/site-packages/wandb/sdk/wandb_run.py", line 387, in wrapper
    return func(self, *args, **kwargs)
  File "/Users/kovarthanan/Acedamic/City, University of London/INM705 - Image Analysis/AI-Generated-Image-Detector/.venv/lib/python3.10/site-packages/wandb/sdk/wandb_run.py", line 2190, in _finish
    with telemetry.context(run=self) as tel:
  File "/Users/kovarthanan/Acedamic/City, University of London/INM705 - Image Analysis/AI-Generated-Image-Detector/.venv/lib/python3.10/site-packages/wandb/sdk/lib/telemetry.py", line 42, in __exit__
    self._run._telemetry_callback(self._obj)
  File "/Users/kovarthanan/Acedamic/City, University of London/INM705 - Image Analysis/AI-Generated-Image-Detector/.venv/lib/python3.10/site-packages/wandb/sdk/wandb_run.py", line 783, in _telemetry_callback
    self._telemetry_flush()
  File "/Users/kovarthanan/Acedamic/City, University of London/INM705 - Image Analysis/AI-Generated-Image-Detector/.venv/lib/python3.10/site-packages/wandb/sdk/wandb_run.py", line 796, in _telemetry_flush
    self._backend.interface._publish_telemetry(self._telemetry_obj)
  File "/Users/kovarthanan/Acedamic/City, University of London/INM705 - Image Analysis/AI-Generated-Image-Detector/.venv/lib/python3.10/site-packages/wandb/sdk/interface/interface_shared.py", line 60, in _publish_telemetry
    self._publish(rec)
  File "/Users/kovarthanan/Acedamic/City, University of London/INM705 - Image Analysis/AI-Generated-Image-Detector/.venv/lib/python3.10/site-packages/wandb/sdk/interface/interface_sock.py", line 39, in _publish
    self._sock_client.send_record_publish(record)
  File "/Users/kovarthanan/Acedamic/City, University of London/INM705 - Image Analysis/AI-Generated-Image-Detector/.venv/lib/python3.10/site-packages/wandb/sdk/lib/sock_client.py", line 174, in send_record_publish
    self.send_server_request(server_req)
  File "/Users/kovarthanan/Acedamic/City, University of London/INM705 - Image Analysis/AI-Generated-Image-Detector/.venv/lib/python3.10/site-packages/wandb/sdk/lib/sock_client.py", line 154, in send_server_request
    self._send_message(msg)
  File "/Users/kovarthanan/Acedamic/City, University of London/INM705 - Image Analysis/AI-Generated-Image-Detector/.venv/lib/python3.10/site-packages/wandb/sdk/lib/sock_client.py", line 151, in _send_message
    self._sendall_with_error_handle(header + data)
  File "/Users/kovarthanan/Acedamic/City, University of London/INM705 - Image Analysis/AI-Generated-Image-Detector/.venv/lib/python3.10/site-packages/wandb/sdk/lib/sock_client.py", line 130, in _sendall_with_error_handle
    sent = self._sock.send(data)
BrokenPipeError: [Errno 32] Broken pipe
