2025-04-22 08:43:45,173 INFO    MainThread:48281 [wandb_setup.py:_flush():67] Current SDK version is 0.19.9
2025-04-22 08:43:45,173 INFO    MainThread:48281 [wandb_setup.py:_flush():67] Configure stats pid to 48281
2025-04-22 08:43:45,173 INFO    MainThread:48281 [wandb_setup.py:_flush():67] Loading settings from /Users/kovarthanan/.config/wandb/settings
2025-04-22 08:43:45,173 INFO    MainThread:48281 [wandb_setup.py:_flush():67] Loading settings from /Users/kovarthanan/Acedamic/City, University of London/INM705 - Image Analysis/AI-Generated-Image-Detector/wandb/settings
2025-04-22 08:43:45,173 INFO    MainThread:48281 [wandb_setup.py:_flush():67] Loading settings from environment variables
2025-04-22 08:43:45,173 INFO    MainThread:48281 [wandb_init.py:setup_run_log_directory():662] Logging user logs to /Users/kovarthanan/Acedamic/City, University of London/INM705 - Image Analysis/AI-Generated-Image-Detector/wandb/run-20250422_084345-mzj6be1w/logs/debug.log
2025-04-22 08:43:45,173 INFO    MainThread:48281 [wandb_init.py:setup_run_log_directory():663] Logging internal logs to /Users/kovarthanan/Acedamic/City, University of London/INM705 - Image Analysis/AI-Generated-Image-Detector/wandb/run-20250422_084345-mzj6be1w/logs/debug-internal.log
2025-04-22 08:43:45,173 INFO    MainThread:48281 [wandb_init.py:monkeypatch_ipython():581] configuring jupyter hooks <wandb.sdk.wandb_init._WandbInit object at 0x144019900>
2025-04-22 08:43:45,173 INFO    MainThread:48281 [wandb_init.py:init():781] calling init triggers
2025-04-22 08:43:45,173 INFO    MainThread:48281 [wandb_init.py:init():786] wandb.init called with sweep_config: {}
config: {'epochs': 5, 'batch_size': 32, 'lr': 5e-05, '_wandb': {}}
2025-04-22 08:43:45,173 INFO    MainThread:48281 [wandb_init.py:init():809] starting backend
2025-04-22 08:43:45,173 INFO    MainThread:48281 [wandb_init.py:init():813] sending inform_init request
2025-04-22 08:43:45,201 INFO    MainThread:48281 [backend.py:_multiprocessing_setup():101] multiprocessing start_methods=spawn,fork,forkserver, using: spawn
2025-04-22 08:43:45,201 INFO    MainThread:48281 [wandb_init.py:init():823] backend started and connected
2025-04-22 08:43:45,208 INFO    MainThread:48281 [wandb_run.py:_label_probe_notebook():1267] probe notebook
2025-04-22 08:43:45,211 INFO    MainThread:48281 [wandb_init.py:init():915] updated telemetry
2025-04-22 08:43:45,234 INFO    MainThread:48281 [wandb_init.py:init():939] communicating run to backend with 90.0 second timeout
2025-04-22 08:44:16,441 INFO    Thread-6 (wrapped_target):48281 [retry.py:__call__():175] [no run ID] Retry attempt failed:
Traceback (most recent call last):
  File "/Users/kovarthanan/Acedamic/City, University of London/INM705 - Image Analysis/AI-Generated-Image-Detector/.venv/lib/python3.10/site-packages/urllib3/connectionpool.py", line 464, in _make_request
    self._validate_conn(conn)
  File "/Users/kovarthanan/Acedamic/City, University of London/INM705 - Image Analysis/AI-Generated-Image-Detector/.venv/lib/python3.10/site-packages/urllib3/connectionpool.py", line 1093, in _validate_conn
    conn.connect()
  File "/Users/kovarthanan/Acedamic/City, University of London/INM705 - Image Analysis/AI-Generated-Image-Detector/.venv/lib/python3.10/site-packages/urllib3/connection.py", line 741, in connect
    sock_and_verified = _ssl_wrap_socket_and_match_hostname(
  File "/Users/kovarthanan/Acedamic/City, University of London/INM705 - Image Analysis/AI-Generated-Image-Detector/.venv/lib/python3.10/site-packages/urllib3/connection.py", line 920, in _ssl_wrap_socket_and_match_hostname
    ssl_sock = ssl_wrap_socket(
  File "/Users/kovarthanan/Acedamic/City, University of London/INM705 - Image Analysis/AI-Generated-Image-Detector/.venv/lib/python3.10/site-packages/urllib3/util/ssl_.py", line 480, in ssl_wrap_socket
    ssl_sock = _ssl_wrap_socket_impl(sock, context, tls_in_tls, server_hostname)
  File "/Users/kovarthanan/Acedamic/City, University of London/INM705 - Image Analysis/AI-Generated-Image-Detector/.venv/lib/python3.10/site-packages/urllib3/util/ssl_.py", line 524, in _ssl_wrap_socket_impl
    return ssl_context.wrap_socket(sock, server_hostname=server_hostname)
  File "/Library/Frameworks/Python.framework/Versions/3.10/lib/python3.10/ssl.py", line 512, in wrap_socket
    return self.sslsocket_class._create(
  File "/Library/Frameworks/Python.framework/Versions/3.10/lib/python3.10/ssl.py", line 1070, in _create
    self.do_handshake()
  File "/Library/Frameworks/Python.framework/Versions/3.10/lib/python3.10/ssl.py", line 1341, in do_handshake
    self._sslobj.do_handshake()
TimeoutError: _ssl.c:980: The handshake operation timed out

The above exception was the direct cause of the following exception:

Traceback (most recent call last):
  File "/Users/kovarthanan/Acedamic/City, University of London/INM705 - Image Analysis/AI-Generated-Image-Detector/.venv/lib/python3.10/site-packages/requests/adapters.py", line 667, in send
    resp = conn.urlopen(
  File "/Users/kovarthanan/Acedamic/City, University of London/INM705 - Image Analysis/AI-Generated-Image-Detector/.venv/lib/python3.10/site-packages/urllib3/connectionpool.py", line 841, in urlopen
    retries = retries.increment(
  File "/Users/kovarthanan/Acedamic/City, University of London/INM705 - Image Analysis/AI-Generated-Image-Detector/.venv/lib/python3.10/site-packages/urllib3/util/retry.py", line 474, in increment
    raise reraise(type(error), error, _stacktrace)
  File "/Users/kovarthanan/Acedamic/City, University of London/INM705 - Image Analysis/AI-Generated-Image-Detector/.venv/lib/python3.10/site-packages/urllib3/util/util.py", line 39, in reraise
    raise value
  File "/Users/kovarthanan/Acedamic/City, University of London/INM705 - Image Analysis/AI-Generated-Image-Detector/.venv/lib/python3.10/site-packages/urllib3/connectionpool.py", line 787, in urlopen
    response = self._make_request(
  File "/Users/kovarthanan/Acedamic/City, University of London/INM705 - Image Analysis/AI-Generated-Image-Detector/.venv/lib/python3.10/site-packages/urllib3/connectionpool.py", line 488, in _make_request
    raise new_e
  File "/Users/kovarthanan/Acedamic/City, University of London/INM705 - Image Analysis/AI-Generated-Image-Detector/.venv/lib/python3.10/site-packages/urllib3/connectionpool.py", line 466, in _make_request
    self._raise_timeout(err=e, url=url, timeout_value=conn.timeout)
  File "/Users/kovarthanan/Acedamic/City, University of London/INM705 - Image Analysis/AI-Generated-Image-Detector/.venv/lib/python3.10/site-packages/urllib3/connectionpool.py", line 367, in _raise_timeout
    raise ReadTimeoutError(
urllib3.exceptions.ReadTimeoutError: HTTPSConnectionPool(host='api.wandb.ai', port=443): Read timed out. (read timeout=20)

During handling of the above exception, another exception occurred:

Traceback (most recent call last):
  File "/Users/kovarthanan/Acedamic/City, University of London/INM705 - Image Analysis/AI-Generated-Image-Detector/.venv/lib/python3.10/site-packages/wandb/sdk/lib/retry.py", line 134, in __call__
    result = self._call_fn(*args, **kwargs)
  File "/Users/kovarthanan/Acedamic/City, University of London/INM705 - Image Analysis/AI-Generated-Image-Detector/.venv/lib/python3.10/site-packages/wandb/sdk/internal/internal_api.py", line 402, in execute
    return self.client.execute(*args, **kwargs)  # type: ignore
  File "/Users/kovarthanan/Acedamic/City, University of London/INM705 - Image Analysis/AI-Generated-Image-Detector/.venv/lib/python3.10/site-packages/wandb/vendor/gql-0.2.0/wandb_gql/client.py", line 52, in execute
    result = self._get_result(document, *args, **kwargs)
  File "/Users/kovarthanan/Acedamic/City, University of London/INM705 - Image Analysis/AI-Generated-Image-Detector/.venv/lib/python3.10/site-packages/wandb/vendor/gql-0.2.0/wandb_gql/client.py", line 60, in _get_result
    return self.transport.execute(document, *args, **kwargs)
  File "/Users/kovarthanan/Acedamic/City, University of London/INM705 - Image Analysis/AI-Generated-Image-Detector/.venv/lib/python3.10/site-packages/wandb/sdk/lib/gql_request.py", line 58, in execute
    request = self.session.post(self.url, **post_args)
  File "/Users/kovarthanan/Acedamic/City, University of London/INM705 - Image Analysis/AI-Generated-Image-Detector/.venv/lib/python3.10/site-packages/requests/sessions.py", line 637, in post
    return self.request("POST", url, data=data, json=json, **kwargs)
  File "/Users/kovarthanan/Acedamic/City, University of London/INM705 - Image Analysis/AI-Generated-Image-Detector/.venv/lib/python3.10/site-packages/requests/sessions.py", line 589, in request
    resp = self.send(prep, **send_kwargs)
  File "/Users/kovarthanan/Acedamic/City, University of London/INM705 - Image Analysis/AI-Generated-Image-Detector/.venv/lib/python3.10/site-packages/requests/sessions.py", line 703, in send
    r = adapter.send(request, **kwargs)
  File "/Users/kovarthanan/Acedamic/City, University of London/INM705 - Image Analysis/AI-Generated-Image-Detector/.venv/lib/python3.10/site-packages/requests/adapters.py", line 713, in send
    raise ReadTimeout(e, request=request)
requests.exceptions.ReadTimeout: HTTPSConnectionPool(host='api.wandb.ai', port=443): Read timed out. (read timeout=20)
