2025-04-21 04:41:59,544 INFO    MainThread:22173 [wandb_setup.py:_flush():67] Current SDK version is 0.19.9
2025-04-21 04:41:59,545 INFO    MainThread:22173 [wandb_setup.py:_flush():67] Configure stats pid to 22173
2025-04-21 04:41:59,545 INFO    MainThread:22173 [wandb_setup.py:_flush():67] Loading settings from /Users/kovarthanan/.config/wandb/settings
2025-04-21 04:41:59,545 INFO    MainThread:22173 [wandb_setup.py:_flush():67] Loading settings from /Users/kovarthanan/Acedamic/City, University of London/INM705 - Image Analysis/AI-Generated-Image-Detector/wandb/settings
2025-04-21 04:41:59,545 INFO    MainThread:22173 [wandb_setup.py:_flush():67] Loading settings from environment variables
2025-04-21 04:41:59,545 INFO    MainThread:22173 [wandb_init.py:setup_run_log_directory():662] Logging user logs to /Users/kovarthanan/Acedamic/City, University of London/INM705 - Image Analysis/AI-Generated-Image-Detector/wandb/run-20250421_044159-3jydnnut/logs/debug.log
2025-04-21 04:41:59,545 INFO    MainThread:22173 [wandb_init.py:setup_run_log_directory():663] Logging internal logs to /Users/kovarthanan/Acedamic/City, University of London/INM705 - Image Analysis/AI-Generated-Image-Detector/wandb/run-20250421_044159-3jydnnut/logs/debug-internal.log
2025-04-21 04:41:59,545 INFO    MainThread:22173 [wandb_init.py:monkeypatch_ipython():581] configuring jupyter hooks <wandb.sdk.wandb_init._WandbInit object at 0x1521ad810>
2025-04-21 04:41:59,545 INFO    MainThread:22173 [wandb_init.py:init():781] calling init triggers
2025-04-21 04:41:59,545 INFO    MainThread:22173 [wandb_init.py:init():786] wandb.init called with sweep_config: {}
config: {'epochs': 5, 'batch_size': 32, 'lr': 5e-05, '_wandb': {}}
2025-04-21 04:41:59,545 INFO    MainThread:22173 [wandb_init.py:init():809] starting backend
2025-04-21 04:41:59,546 INFO    MainThread:22173 [wandb_init.py:init():813] sending inform_init request
2025-04-21 04:41:59,582 INFO    MainThread:22173 [backend.py:_multiprocessing_setup():101] multiprocessing start_methods=spawn,fork,forkserver, using: spawn
2025-04-21 04:41:59,582 INFO    MainThread:22173 [wandb_init.py:init():823] backend started and connected
2025-04-21 04:41:59,589 INFO    MainThread:22173 [wandb_run.py:_label_probe_notebook():1267] probe notebook
2025-04-21 04:41:59,594 INFO    MainThread:22173 [wandb_init.py:init():915] updated telemetry
2025-04-21 04:41:59,616 INFO    MainThread:22173 [wandb_init.py:init():939] communicating run to backend with 90.0 second timeout
2025-04-21 04:42:00,738 INFO    MainThread:22173 [wandb_init.py:init():1014] starting run threads in backend
2025-04-21 04:42:00,804 INFO    MainThread:22173 [wandb_run.py:_console_start():2454] atexit reg
2025-04-21 04:42:00,804 INFO    MainThread:22173 [wandb_run.py:_redirect():2306] redirect: wrap_raw
2025-04-21 04:42:00,804 INFO    MainThread:22173 [wandb_run.py:_redirect():2371] Wrapping output streams.
2025-04-21 04:42:00,804 INFO    MainThread:22173 [wandb_run.py:_redirect():2394] Redirects installed.
2025-04-21 04:42:00,806 INFO    MainThread:22173 [wandb_init.py:init():1056] run started, returning control to user process
2025-04-21 04:42:00,806 INFO    MainThread:22173 [jupyter.py:save_ipynb():384] [no run ID] not saving jupyter notebook
2025-04-21 04:42:00,806 INFO    MainThread:22173 [wandb_init.py:_pause_backend():546] [no run ID] pausing backend
2025-04-21 04:42:00,810 INFO    MainThread:22173 [wandb_init.py:_resume_backend():551] [no run ID] resuming backend
2025-04-21 04:42:00,811 INFO    MainThread:22173 [jupyter.py:save_ipynb():384] [no run ID] not saving jupyter notebook
2025-04-21 04:42:00,812 INFO    MainThread:22173 [wandb_init.py:_pause_backend():546] [no run ID] pausing backend
2025-04-21 04:42:00,816 INFO    MainThread:22173 [wandb_init.py:_resume_backend():551] [no run ID] resuming backend
2025-04-21 04:42:02,041 INFO    MainThread:22173 [wandb_watch.py:_watch():71] Watching
2025-04-21 04:42:02,043 INFO    MainThread:22173 [jupyter.py:save_ipynb():384] [no run ID] not saving jupyter notebook
2025-04-21 04:42:02,043 INFO    MainThread:22173 [wandb_init.py:_pause_backend():546] [no run ID] pausing backend
2025-04-21 04:42:02,086 INFO    MainThread:22173 [wandb_init.py:_resume_backend():551] [no run ID] resuming backend
2025-04-21 04:50:07,216 WARNING MsgRouterThr:22173 [router.py:message_loop():63] [no run ID] message_loop has been closed
Traceback (most recent call last):
  File "/Users/kovarthanan/Acedamic/City, University of London/INM705 - Image Analysis/AI-Generated-Image-Detector/.venv/lib/python3.10/site-packages/wandb/sdk/lib/sock_client.py", line 208, in _read_packet_bytes
    data = self._sock.recv(self._bufsize)
ConnectionResetError: [Errno 54] Connection reset by peer

The above exception was the direct cause of the following exception:

Traceback (most recent call last):
  File "/Users/kovarthanan/Acedamic/City, University of London/INM705 - Image Analysis/AI-Generated-Image-Detector/.venv/lib/python3.10/site-packages/wandb/sdk/interface/router_sock.py", line 27, in _read_message
    return self._sock_client.read_server_response(timeout=1)
  File "/Users/kovarthanan/Acedamic/City, University of London/INM705 - Image Analysis/AI-Generated-Image-Detector/.venv/lib/python3.10/site-packages/wandb/sdk/lib/sock_client.py", line 235, in read_server_response
    data = self._read_packet_bytes(timeout=timeout)
  File "/Users/kovarthanan/Acedamic/City, University of London/INM705 - Image Analysis/AI-Generated-Image-Detector/.venv/lib/python3.10/site-packages/wandb/sdk/lib/sock_client.py", line 212, in _read_packet_bytes
    raise SockClientClosedError from e
wandb.sdk.lib.sock_client.SockClientClosedError

The above exception was the direct cause of the following exception:

Traceback (most recent call last):
  File "/Users/kovarthanan/Acedamic/City, University of London/INM705 - Image Analysis/AI-Generated-Image-Detector/.venv/lib/python3.10/site-packages/wandb/sdk/interface/router.py", line 56, in message_loop
    msg = self._read_message()
  File "/Users/kovarthanan/Acedamic/City, University of London/INM705 - Image Analysis/AI-Generated-Image-Detector/.venv/lib/python3.10/site-packages/wandb/sdk/interface/router_sock.py", line 29, in _read_message
    raise MessageRouterClosedError from e
wandb.sdk.interface.router.MessageRouterClosedError
2025-04-21 04:50:07,258 INFO    MsgRouterThr:22173 [mailbox.py:close():129] [no run ID] Closing mailbox, abandoning 1 handles.
2025-04-21 04:50:07,467 INFO    MainThread:22173 [jupyter.py:save_ipynb():384] [no run ID] not saving jupyter notebook
2025-04-21 04:50:07,467 INFO    MainThread:22173 [wandb_init.py:_pause_backend():546] [no run ID] pausing backend
2025-04-21 04:50:07,467 ERROR   MainThread:22173 [redirect.py:_on_write():661] [no run ID] error in stdout callback
Traceback (most recent call last):
  File "/Users/kovarthanan/Acedamic/City, University of London/INM705 - Image Analysis/AI-Generated-Image-Detector/.venv/lib/python3.10/site-packages/IPython/core/events.py", line 82, in trigger
    func(*args, **kwargs)
  File "/Users/kovarthanan/Acedamic/City, University of London/INM705 - Image Analysis/AI-Generated-Image-Detector/.venv/lib/python3.10/site-packages/wandb/sdk/wandb_init.py", line 547, in _pause_backend
    self.backend.interface.publish_pause()
  File "/Users/kovarthanan/Acedamic/City, University of London/INM705 - Image Analysis/AI-Generated-Image-Detector/.venv/lib/python3.10/site-packages/wandb/sdk/interface/interface.py", line 769, in publish_pause
    self._publish_pause(pause)
  File "/Users/kovarthanan/Acedamic/City, University of London/INM705 - Image Analysis/AI-Generated-Image-Detector/.venv/lib/python3.10/site-packages/wandb/sdk/interface/interface_shared.py", line 289, in _publish_pause
    self._publish(rec)
  File "/Users/kovarthanan/Acedamic/City, University of London/INM705 - Image Analysis/AI-Generated-Image-Detector/.venv/lib/python3.10/site-packages/wandb/sdk/interface/interface_sock.py", line 39, in _publish
    self._sock_client.send_record_publish(record)
  File "/Users/kovarthanan/Acedamic/City, University of London/INM705 - Image Analysis/AI-Generated-Image-Detector/.venv/lib/python3.10/site-packages/wandb/sdk/lib/sock_client.py", line 174, in send_record_publish
    self.send_server_request(server_req)
  File "/Users/kovarthanan/Acedamic/City, University of London/INM705 - Image Analysis/AI-Generated-Image-Detector/.venv/lib/python3.10/site-packages/wandb/sdk/lib/sock_client.py", line 154, in send_server_request
    self._send_message(msg)
  File "/Users/kovarthanan/Acedamic/City, University of London/INM705 - Image Analysis/AI-Generated-Image-Detector/.venv/lib/python3.10/site-packages/wandb/sdk/lib/sock_client.py", line 151, in _send_message
    self._sendall_with_error_handle(header + data)
  File "/Users/kovarthanan/Acedamic/City, University of London/INM705 - Image Analysis/AI-Generated-Image-Detector/.venv/lib/python3.10/site-packages/wandb/sdk/lib/sock_client.py", line 130, in _sendall_with_error_handle
    sent = self._sock.send(data)
BrokenPipeError: [Errno 32] Broken pipe

During handling of the above exception, another exception occurred:

Traceback (most recent call last):
  File "/Users/kovarthanan/Acedamic/City, University of London/INM705 - Image Analysis/AI-Generated-Image-Detector/.venv/lib/python3.10/site-packages/wandb/sdk/lib/redirect.py", line 659, in _on_write
    cb(written_data)
  File "/Users/kovarthanan/Acedamic/City, University of London/INM705 - Image Analysis/AI-Generated-Image-Detector/.venv/lib/python3.10/site-packages/wandb/sdk/wandb_run.py", line 2375, in <lambda>
    lambda data: self._console_raw_callback("stdout", data),
  File "/Users/kovarthanan/Acedamic/City, University of London/INM705 - Image Analysis/AI-Generated-Image-Detector/.venv/lib/python3.10/site-packages/wandb/sdk/wandb_run.py", line 387, in wrapper
    return func(self, *args, **kwargs)
  File "/Users/kovarthanan/Acedamic/City, University of London/INM705 - Image Analysis/AI-Generated-Image-Detector/.venv/lib/python3.10/site-packages/wandb/sdk/wandb_run.py", line 435, in wrapper_fn
    return func(self, *args, **kwargs)
  File "/Users/kovarthanan/Acedamic/City, University of London/INM705 - Image Analysis/AI-Generated-Image-Detector/.venv/lib/python3.10/site-packages/wandb/sdk/wandb_run.py", line 1518, in _console_raw_callback
    self._backend.interface.publish_output_raw(name, data)
  File "/Users/kovarthanan/Acedamic/City, University of London/INM705 - Image Analysis/AI-Generated-Image-Detector/.venv/lib/python3.10/site-packages/wandb/sdk/interface/interface.py", line 761, in publish_output_raw
    self._publish_output_raw(o)
  File "/Users/kovarthanan/Acedamic/City, University of London/INM705 - Image Analysis/AI-Generated-Image-Detector/.venv/lib/python3.10/site-packages/wandb/sdk/interface/interface_shared.py", line 38, in _publish_output_raw
    self._publish(rec)
  File "/Users/kovarthanan/Acedamic/City, University of London/INM705 - Image Analysis/AI-Generated-Image-Detector/.venv/lib/python3.10/site-packages/wandb/sdk/interface/interface_sock.py", line 39, in _publish
    self._sock_client.send_record_publish(record)
  File "/Users/kovarthanan/Acedamic/City, University of London/INM705 - Image Analysis/AI-Generated-Image-Detector/.venv/lib/python3.10/site-packages/wandb/sdk/lib/sock_client.py", line 174, in send_record_publish
    self.send_server_request(server_req)
  File "/Users/kovarthanan/Acedamic/City, University of London/INM705 - Image Analysis/AI-Generated-Image-Detector/.venv/lib/python3.10/site-packages/wandb/sdk/lib/sock_client.py", line 154, in send_server_request
    self._send_message(msg)
  File "/Users/kovarthanan/Acedamic/City, University of London/INM705 - Image Analysis/AI-Generated-Image-Detector/.venv/lib/python3.10/site-packages/wandb/sdk/lib/sock_client.py", line 151, in _send_message
    self._sendall_with_error_handle(header + data)
  File "/Users/kovarthanan/Acedamic/City, University of London/INM705 - Image Analysis/AI-Generated-Image-Detector/.venv/lib/python3.10/site-packages/wandb/sdk/lib/sock_client.py", line 130, in _sendall_with_error_handle
    sent = self._sock.send(data)
BrokenPipeError: [Errno 32] Broken pipe
2025-04-21 04:50:07,471 ERROR   MainThread:22173 [redirect.py:_on_write():661] [no run ID] error in stdout callback
Traceback (most recent call last):
  File "/Users/kovarthanan/Acedamic/City, University of London/INM705 - Image Analysis/AI-Generated-Image-Detector/.venv/lib/python3.10/site-packages/IPython/core/events.py", line 82, in trigger
    func(*args, **kwargs)
  File "/Users/kovarthanan/Acedamic/City, University of London/INM705 - Image Analysis/AI-Generated-Image-Detector/.venv/lib/python3.10/site-packages/wandb/sdk/wandb_init.py", line 547, in _pause_backend
    self.backend.interface.publish_pause()
  File "/Users/kovarthanan/Acedamic/City, University of London/INM705 - Image Analysis/AI-Generated-Image-Detector/.venv/lib/python3.10/site-packages/wandb/sdk/interface/interface.py", line 769, in publish_pause
    self._publish_pause(pause)
  File "/Users/kovarthanan/Acedamic/City, University of London/INM705 - Image Analysis/AI-Generated-Image-Detector/.venv/lib/python3.10/site-packages/wandb/sdk/interface/interface_shared.py", line 289, in _publish_pause
    self._publish(rec)
  File "/Users/kovarthanan/Acedamic/City, University of London/INM705 - Image Analysis/AI-Generated-Image-Detector/.venv/lib/python3.10/site-packages/wandb/sdk/interface/interface_sock.py", line 39, in _publish
    self._sock_client.send_record_publish(record)
  File "/Users/kovarthanan/Acedamic/City, University of London/INM705 - Image Analysis/AI-Generated-Image-Detector/.venv/lib/python3.10/site-packages/wandb/sdk/lib/sock_client.py", line 174, in send_record_publish
    self.send_server_request(server_req)
  File "/Users/kovarthanan/Acedamic/City, University of London/INM705 - Image Analysis/AI-Generated-Image-Detector/.venv/lib/python3.10/site-packages/wandb/sdk/lib/sock_client.py", line 154, in send_server_request
    self._send_message(msg)
  File "/Users/kovarthanan/Acedamic/City, University of London/INM705 - Image Analysis/AI-Generated-Image-Detector/.venv/lib/python3.10/site-packages/wandb/sdk/lib/sock_client.py", line 151, in _send_message
    self._sendall_with_error_handle(header + data)
  File "/Users/kovarthanan/Acedamic/City, University of London/INM705 - Image Analysis/AI-Generated-Image-Detector/.venv/lib/python3.10/site-packages/wandb/sdk/lib/sock_client.py", line 130, in _sendall_with_error_handle
    sent = self._sock.send(data)
BrokenPipeError: [Errno 32] Broken pipe

During handling of the above exception, another exception occurred:

Traceback (most recent call last):
  File "/Users/kovarthanan/Acedamic/City, University of London/INM705 - Image Analysis/AI-Generated-Image-Detector/.venv/lib/python3.10/site-packages/wandb/sdk/lib/redirect.py", line 659, in _on_write
    cb(written_data)
  File "/Users/kovarthanan/Acedamic/City, University of London/INM705 - Image Analysis/AI-Generated-Image-Detector/.venv/lib/python3.10/site-packages/wandb/sdk/wandb_run.py", line 2375, in <lambda>
    lambda data: self._console_raw_callback("stdout", data),
  File "/Users/kovarthanan/Acedamic/City, University of London/INM705 - Image Analysis/AI-Generated-Image-Detector/.venv/lib/python3.10/site-packages/wandb/sdk/wandb_run.py", line 387, in wrapper
    return func(self, *args, **kwargs)
  File "/Users/kovarthanan/Acedamic/City, University of London/INM705 - Image Analysis/AI-Generated-Image-Detector/.venv/lib/python3.10/site-packages/wandb/sdk/wandb_run.py", line 435, in wrapper_fn
    return func(self, *args, **kwargs)
  File "/Users/kovarthanan/Acedamic/City, University of London/INM705 - Image Analysis/AI-Generated-Image-Detector/.venv/lib/python3.10/site-packages/wandb/sdk/wandb_run.py", line 1518, in _console_raw_callback
    self._backend.interface.publish_output_raw(name, data)
  File "/Users/kovarthanan/Acedamic/City, University of London/INM705 - Image Analysis/AI-Generated-Image-Detector/.venv/lib/python3.10/site-packages/wandb/sdk/interface/interface.py", line 761, in publish_output_raw
    self._publish_output_raw(o)
  File "/Users/kovarthanan/Acedamic/City, University of London/INM705 - Image Analysis/AI-Generated-Image-Detector/.venv/lib/python3.10/site-packages/wandb/sdk/interface/interface_shared.py", line 38, in _publish_output_raw
    self._publish(rec)
  File "/Users/kovarthanan/Acedamic/City, University of London/INM705 - Image Analysis/AI-Generated-Image-Detector/.venv/lib/python3.10/site-packages/wandb/sdk/interface/interface_sock.py", line 39, in _publish
    self._sock_client.send_record_publish(record)
  File "/Users/kovarthanan/Acedamic/City, University of London/INM705 - Image Analysis/AI-Generated-Image-Detector/.venv/lib/python3.10/site-packages/wandb/sdk/lib/sock_client.py", line 174, in send_record_publish
    self.send_server_request(server_req)
  File "/Users/kovarthanan/Acedamic/City, University of London/INM705 - Image Analysis/AI-Generated-Image-Detector/.venv/lib/python3.10/site-packages/wandb/sdk/lib/sock_client.py", line 154, in send_server_request
    self._send_message(msg)
  File "/Users/kovarthanan/Acedamic/City, University of London/INM705 - Image Analysis/AI-Generated-Image-Detector/.venv/lib/python3.10/site-packages/wandb/sdk/lib/sock_client.py", line 151, in _send_message
    self._sendall_with_error_handle(header + data)
  File "/Users/kovarthanan/Acedamic/City, University of London/INM705 - Image Analysis/AI-Generated-Image-Detector/.venv/lib/python3.10/site-packages/wandb/sdk/lib/sock_client.py", line 130, in _sendall_with_error_handle
    sent = self._sock.send(data)
BrokenPipeError: [Errno 32] Broken pipe
